Workbook

Sheet zero (1995-2023)
A1: ITA-ROE-GradientBoostingClassifier | I1: EU-ROE-GradientBoostingClassifier | Q1: USA-ROE-GradientBoostingClassifier
B2: precision | C2: recall | D2: f1-score | E2: support | F2: confusion matrix | G2: roc-auc score | J2: precision | K2: recall | L2: f1-score | M2: support | N2: confusion matrix | O2: roc-auc score | R2: precision | S2: recall | T2: f1-score | U2: support | V2: confusion matrix | W2: roc-auc score
A3: 0 | B3: 0.71 | C3: 0.62 | D3: 0.66 | E3: 196 | F3: [[121 75] [ 50 116]] | G3: 0.65807106 | I3: 0 | J3: 0.69 | K3: 0.61 | L3: 0.65 | M3: 1099 | N3: [[674 425] [297 604] | O3: 0.64182553 | Q3: 0 | R3: 0.73 | S3: 0.52 | T3: 0.61 | U3: 991 | V3: [[519 472] [195 814]] | W3: 0.66522638
A4: 1 | B4: 0.61 | C4: 0.7 | D4: 0.65 | E4: 166 | I4: 1 | J4: 0.59 | K4: 0.67 | L4: 0.63 | M4: 901 | Q4: 1 | R4: 0.63 | S4: 0.81 | T4: 0.71 | U4: 1009
A5: accuracy | D5: 0.65 | E5: 362 | I5: accuracy | L5: 0.64 | M5: 2000 | Q5: accuracy | T5: 0.67 | U5: 2000
A6: macro avg | B6: 0.66 | C6: 0.66 | D6: 0.65 | E6: 362 | I6: macro avg | J6: 0.64 | K6: 0.64 | L6: 0.64 | M6: 2000 | Q6: macro avg | R6: 0.68 | S6: 0.67 | T6: 0.66 | U6: 2000
A7: weighted avg | B7: 0.66 | C7: 0.65 | D7: 0.66 | E7: 362 | I7: weighted avg | J7: 0.65 | K7: 0.64 | L7: 0.64 | M7: 2000 | Q7: weighted avg | R7: 0.68 | S7: 0.67 | T7: 0.66 | U7: 2000
A9: ITA-ROE-RandomForestClassifier | I9: EU-ROE-RandomForestClassifier | Q9: USA-ROE-RandomForestClassifier
B10: precision | C10: recall | D10: f1-score | E10: support | F10: confusion matrix | G10: roc-auc score | J10: precision | K10: recall | L10: f1-score | M10: support | N10: confusion matrix | O10: roc-auc score | R10: precision | S10: recall | T10: f1-score | U10: support | V10: confusion matrix | W10: roc-auc score
A11: 0 | B11: 0.67 | C11: 0.69 | D11: 0.68 | E11: 196 | F11: [[135 61] [ 68 98]] | G11: 0.63956848 | I11: 0 | J11: 0.68 | K11: 0.64 | L11: 0.66 | M11: 1099 | N11: [[703 396] [325 576]] | O11: 0.63948105 | Q11: 0 | R11: 0.69 | S11: 0.59 | T11: 0.64 | U11: 991 | V11: [[584 407] [257 752]] | W11: 0.66729805
A12: 1 | B12: 0.62 | C12: 0.59 | D12: 0.6 | E12: 166 | I12: 1 | J12: 0.59 | K12: 0.64 | L12: 0.62 | M12: 901 | Q12: 1 | R12: 0.65 | S12: 0.75 | T12: 0.69 | U12: 1009
A13: accuracy | D13: 0.64 | E13: 362 | I13: accuracy | L13: 0.64 | M13: 2000 | Q13: accuracy | T13: 0.67 | U13: 2000
A14: macro avg | B14: 0.64 | C14: 0.64 | D14: 0.64 | E14: 362 | I14: macro avg | J14: 0.64 | K14: 0.64 | L14: 0.64 | M14: 2000 | Q14: macro avg | R14: 0.67 | S14: 0.67 | T14: 0.67 | U14: 2000
A15: weighted avg | B15: 0.64 | C15: 0.64 | D15: 0.64 | E15: 362 | I15: weighted avg | J15: 0.64 | K15: 0.64 | L15: 0.64 | M15: 2000 | Q15: weighted avg | R15: 0.67 | S15: 0.67 | T15: 0.67 | U15: 2000
A17: ITA-ROE-MPLClassifier | I17: EU-ROE-MPLClassifier | Q17: USA-ROE-MPLClassifier
B18: precision | C18: recall | D18: f1-score | E18: support | F18: confusion matrix | G18: roc-auc score | J18: precision | K18: recall | L18: f1-score | M18: support | N18: confusion matrix | O18: roc-auc score | R18: precision | S18: recall | T18: f1-score | U18: support | V18: confusion matrix | W18: roc-auc score
A19: 0 | B19: 0.6 | C19: 0.71 | D19: 0.65 | E19: 196 | F19: [[140 56] [ 95 71]] | G19: 0.57099828 | I19: 0 | J19: 0.63 | K19: 0.72 | L19: 0.67 | M19: 1099 | N19: [[791 308] [473 428]] | O19: 0.59738648 | Q19: 0 | R19: 0.63 | S19: 0.52 | T19: 0.57 | U19: 991 | V19: [[511 480] [302 707]] | W19: 0.60816726
A20: 1 | B20: 0.56 | C20: 0.43 | D20: 0.48 | E20: 166 | I20: 1 | J20: 0.58 | K20: 0.48 | L20: 0.52 | M20: 901 | Q20: 1 | R20: 0.6 | S20: 0.7 | T20: 0.64 | U20: 1009
A21: accuracy | D21: 0.58 | E21: 362 | I21: accuracy | L21: 0.61 | M21: 2000 | Q21: accuracy | T21: 0.61 | U21: 2000
A22: macro avg | B22: 0.58 | C22: 0.57 | D22: 0.57 | E22: 362 | I22: macro avg | J22: 0.6 | K22: 0.6 | L22: 0.6 | M22: 2000 | Q22: macro avg | R22: 0.61 | S22: 0.61 | T22: 0.61 | U22: 2000
A23: weighted avg | B23: 0.58 | C23: 0.58 | D23: 0.57 | E23: 362 | I23: weighted avg | J23: 0.61 | K23: 0.61 | L23: 0.6 | M23: 2000 | Q23: weighted avg | R23: 0.61 | S23: 0.61 | T23: 0.61 | U23: 2000
A25: ITA-ROCE-GradientBoostingClassifier | I25: EU-ROCE-GradientBoostingClassifier | Q25: USA-ROCE-GradientBoostingClassifier
B26: precision | C26: recall | D26: f1-score | E26: support | F26: confusion matrix | G26: roc-auc score | J26: precision | K26: recall | L26: f1-score | M26: support | N26: confusion matrix | O26: roc-auc score | R26: precision | S26: recall | T26: f1-score | U26: support | V26: confusion matrix | W26: roc-auc score
A27: 0 | B27: 0.64 | C27: 0.61 | D27: 0.62 | E27: 167 | F27: [[102 65] [ 58 137]] | G27: 0.65667127 | I27: 0 | J27: 0.63 | K27: 0.56 | L27: 0.59 | M27: 958 | N27: [[534 424] [308 734]] | O27: 0.63091293 | Q27: 0 | R27: 0.69 | S27: 0.51 | T27: 0.59 | U27: 812 | V27: [[418 394] [190 998]] | W27: 0.67742283
A28: 1 | B28: 0.68 | C28: 0.7 | D28: 0.69 | E28: 195 | I28: 1 | J28: 0.63 | K28: 0.7 | L28: 0.67 | M28: 1042 | Q28: 1 | R28: 0.72 | S28: 0.84 | T28: 0.77 | U28: 1188
A29: accuracy | D29: 0.66 | E29: 362 | I29: accuracy | L29: 0.63 | M29: 2000 | Q29: accuracy | T29: 0.71 | U29: 2000
A30: macro avg | B30: 0.66 | C30: 0.66 | D30: 0.66 | E30: 362 | I30: macro avg | J30: 0.63 | K30: 0.63 | L30: 0.63 | M30: 2000 | Q30: macro avg | R30: 0.7 | S30: 0.68 | T30: 0.68 | U30: 2000
A31: weighted avg | B31: 0.66 | C31: 0.66 | D31: 0.66 | E31: 362 | I31: weighted avg | J31: 0.63 | K31: 0.63 | L31: 0.63 | M31: 2000 | Q31: weighted avg | R31: 0.7 | S31: 0.71 | T31: 0.7 | U31: 2000
A33: ITA-ROCE-RandomForestClassifier | I33: EU-ROCE-RandomForestClassifier | Q33: USA-ROCE-RandomForestClassifier
B34: precision | C34: recall | D34: f1-score | E34: support | F34: confusion matrix | G34: roc-auc score | J34: precision | K34: recall | L34: f1-score | M34: support | N34: confusion matrix | O34: roc-auc score | R34: precision | S34: recall | T34: f1-score | U34: support | V34: confusion matrix | W34: roc-auc score
A35: 0 | B35: 0.54 | C35: 0.71 | D35: 0.61 | E35: 167 | F35: [[118 49] [ 99 96]] | G35: 0.59944726 | I35: 0 | J35: 0.62 | K35: 0.65 | L35: 0.64 | M35: 958 | N35: [[619 339] [372 670]] | O35: 0.64456601 | Q35: 0 | R35: 0.63 | S35: 0.58 | T35: 0.61 | U35: 812 | V35: [[475 337] [281 907]] | W35: 0.67422169
A36: 1 | B36: 0.66 | C36: 0.49 | D36: 0.56 | E36: 195 | I36: 1 | J36: 0.66 | K36: 0.64 | L36: 0.65 | M36: 1042 | Q36: 1 | R36: 0.73 | S36: 0.76 | T36: 0.75 | U36: 1188
A37: accuracy | D37: 0.59 | E37: 362 | I37: accuracy | L37: 0.64 | M37: 2000 | Q37: accuracy | T37: 0.69 | U37: 2000
A38: macro avg | B38: 0.6 | C38: 0.6 | D38: 0.59 | E38: 362 | I38: macro avg | J38: 0.64 | K38: 0.64 | L38: 0.64 | M38: 2000 | Q38: macro avg | R38: 0.68 | S38: 0.67 | T38: 0.68 | U38: 2000
A39: weighted avg | B39: 0.61 | C39: 0.59 | D39: 0.59 | E39: 362 | I39: weighted avg | J39: 0.65 | K39: 0.64 | L39: 0.64 | M39: 2000 | Q39: weighted avg | R39: 0.69 | S39: 0.69 | T39: 0.69 | U39: 2000
A41: ITA-ROCE-MPLClassifier | I41: EU-ROCE-MPLClassifier | Q41: USA-ROCE-MPLClassifier
B42: precision | C42: recall | D42: f1-score | E42: support | F42: confusion matrix | G42: roc-auc score | J42: precision | K42: recall | L42: f1-score | M42: support | N42: confusion matrix | O42: roc-auc score | R42: precision | S42: recall | T42: f1-score | U42: support | V42: confusion matrix | W42: roc-auc score
A43: 0 | B43: 0.62 | C43: 0.38 | D43: 0.47 | E43: 167 | F43: [[ 63 104] [ 39 156]] | G43: 0.58862275 | I43: 0 | J43: 0.75 | K43: 0 | L43: 0.01 | M43: 958 | N43: [[ 3 955] [ 1 1041]] | O43: 0.50108592 | Q43: 0 | R43: 0.5 | S43: 0 | T43: 0 | U43: 812 | V43: [[ 2 810] [ 2 1186]] | W43: 0.50038978
A44: 1 | B44: 0.6 | C44: 0.8 | D44: 0.69 | E44: 195 | I44: 1 | J44: 0.52 | K44: 1 | L44: 0.69 | M44: 1042 | Q44: 1 | R44: 0.59 | S44: 1 | T44: 0.74 | U44: 1188
A45: accuracy | D45: 0.6 | E45: 362 | I45: accuracy | L45: 0.52 | M45: 2000 | Q45: accuracy | T45: 0.59 | U45: 2000
...

Sheet mean (1995-2023)
A1: ITA-ROE-GradientBoostingClassifier | I1: EU-ROE-GradientBoostingClassifier | Q1: USA-ROE-GradientBoostingClassifier
B2: precision | C2: recall | D2: f1-score | E2: support | F2: confusion matrix | G2: roc-auc score | J2: precision | K2: recall | L2: f1-score | M2: support | N2: confusion matrix | O2: roc-auc score | R2: precision | S2: recall | T2: f1-score | U2: support | V2: confusion matrix | W2: roc-auc score
A3: 0 | B3: 0.72 | C3: 0.58 | D3: 0.64 | E3: 196 | F3: [[114 82] [ 45 121]] | G3: 0.65527416 | I3: 0 | J3: 0.69 | K3: 0.62 | L3: 0.65 | M3: 1099 | N3: [[677 422] [298 603]] | O3: 0.64263547 | Q3: 0 | R3: 0.73 | S3: 0.51 | T3: 0.6 | U3: 991 | V3: [[507 484] [184 825]] | W3: 0.66462283
A4: 1 | B4: 0.6 | C4: 0.73 | D4: 0.66 | E4: 166 | I4: 1 | J4: 0.59 | K4: 0.67 | L4: 0.63 | M4: 901 | Q4: 1 | R4: 0.63 | S4: 0.82 | T4: 0.71 | U4: 1009
A5: accuracy | D5: 0.65 | E5: 362 | I5: accuracy | L5: 0.64 | M5: 2000 | Q5: accuracy | T5: 0.67 | U5: 2000
A6: macro avg | B6: 0.66 | C6: 0.66 | D6: 0.65 | E6: 362 | I6: macro avg | J6: 0.64 | K6: 0.64 | L6: 0.64 | M6: 2000 | Q6: macro avg | R6: 0.68 | S6: 0.66 | T6: 0.66 | U6: 2000
A7: weighted avg | B7: 0.66 | C7: 0.65 | D7: 0.65 | E7: 362 | I7: weighted avg | J7: 0.65 | K7: 0.64 | L7: 0.64 | M7: 2000 | Q7: weighted avg | R7: 0.68 | S7: 0.67 | T7: 0.66 | U7: 2000
A9: ITA-ROE-RandomForestClassifier | I9: EU-ROE-RandomForestClassifier | Q9: USA-ROE-RandomForestClassifier
B10: precision | C10: recall | D10: f1-score | E10: support | F10: confusion matrix | G10: roc-auc score | J10: precision | K10: recall | L10: f1-score | M10: support | N10: confusion matrix | O10: roc-auc score | R10: precision | S10: recall | T10: f1-score | U10: support | V10: confusion matrix | W10: roc-auc score
A11: 0 | B11: 0.67 | C11: 0.71 | D11: 0.69 | E11: 196 | F11: [[139 57] [ 69 97]] | G11: 0.64676051 | I11: 0 | J11: 0.69 | K11: 0.65 | L11: 0.67 | M11: 1099 | N11: [[712 387] [322 579]] | O11: 0.6452405 | Q11: 0 | R11: 0.69 | S11: 0.59 | T11: 0.64 | U11: 991 | V11: [[589 402] [259 750]] | W11: 0.66882968
A12: 1 | B12: 0.63 | C12: 0.58 | D12: 0.61 | E12: 166 | I12: 1 | J12: 0.6 | K12: 0.64 | L12: 0.62 | M12: 901 | Q12: 1 | R12: 0.65 | S12: 0.74 | T12: 0.69 | U12: 1009
A13: accuracy | D13: 0.65 | E13: 362 | I13: accuracy | L13: 0.65 | M13: 2000 | Q13: accuracy | T13: 0.67 | U13: 2000
A14: macro avg | B14: 0.65 | C14: 0.65 | D14: 0.65 | E14: 362 | I14: macro avg | J14: 0.64 | K14: 0.65 | L14: 0.64 | M14: 2000 | Q14: macro avg | R14: 0.67 | S14: 0.67 | T14: 0.67 | U14: 2000
A15: weighted avg | B15: 0.65 | C15: 0.65 | D15: 0.65 | E15: 362 | I15: weighted avg | J15: 0.65 | K15: 0.65 | L15: 0.65 | M15: 2000 | Q15: weighted avg | R15: 0.67 | S15: 0.67 | T15: 0.67 | U15: 2000
A17: ITA-ROE-MPLClassifier | I17: EU-ROE-MPLClassifier | Q17: USA-ROE-MPLClassifier
B18: precision | C18: recall | D18: f1-score | E18: support | F18: confusion matrix | G18: roc-auc score | J18: precision | K18: recall | L18: f1-score | M18: support | N18: confusion matrix | O18: roc-auc score | R18: precision | S18: recall | T18: f1-score | U18: support | V18: confusion matrix | W18: roc-auc score
A19: 0 | B19: 0.65 | C19: 0.41 | D19: 0.5 | E19: 196 | F19: [[ 80 116] [ 44 122]] | G19: 0.57155151 | I19: 0 | J19: 1 | K19: 0 | L19: 0 | M19: 1099 | N19: [[ 2 1097] [ 0 901]] | O19: 0.50090992 | Q19: 0 | R19: 0.67 | S19: 0.54 | T19: 0.6 | U19: 991 | V19: [[540 451] [269 740]] | W19: 0.63915177
A20: 1 | B20: 0.51 | C20: 0.73 | D20: 0.6 | E20: 166 | I20: 1 | J20: 0.45 | K20: 1 | L20: 0.62 | M20: 901 | Q20: 1 | R20: 0.62 | S20: 0.73 | T20: 0.67 | U20: 1009
A21: accuracy | D21: 0.56 | E21: 362 | I21: accuracy | L21: 0.45 | M21: 2000 | Q21: accuracy | T21: 0.64 | U21: 2000
A22: macro avg | B22: 0.58 | C22: 0.57 | D22: 0.55 | E22: 362 | I22: macro avg | J22: 0.73 | K22: 0.5 | L22: 0.31 | M22: 2000 | Q22: macro avg | R22: 0.64 | S22: 0.64 | T22: 0.64 | U22: 2000
A23: weighted avg | B23: 0.58 | C23: 0.56 | D23: 0.55 | E23: 362 | I23: weighted avg | J23: 0.75 | K23: 0.45 | L23: 0.28 | M23: 2000 | Q23: weighted avg | R23: 0.64 | S23: 0.64 | T23: 0.64 | U23: 2000
A25: ITA-ROCE-GradientBoostingClassifier | I25: EU-ROCE-GradientBoostingClassifier | Q25: USA-ROCE-GradientBoostingClassifier
B26: precision | C26: recall | D26: f1-score | E26: support | F26: confusion matrix | G26: roc-auc score | J26: precision | K26: recall | L26: f1-score | M26: support | N26: confusion matrix | O26: roc-auc score | R26: precision | S26: recall | T26: f1-score | U26: support | V26: confusion matrix | W26: roc-auc score
A27: 0 | B27: 0.61 | C27: 0.68 | D27: 0.64 | E27: 167 | F27: [[113 54] [ 72 123]] | G27: 0.65370797 | I27: 0 | J27: 0.63 | K27: 0.57 | L27: 0.6 | M27: 958 | N27: [[542 416] [320 722]] | O27: 0.62933014 | Q27: 0 | R27: 0.71 | S27: 0.52 | T27: 0.6 | U27: 812 | V27: [[ 421 391] [ 174 1014]] | W27: 0.68600413
A28: 1 | B28: 0.69 | C28: 0.63 | D28: 0.66 | E28: 195 | I28: 1 | J28: 0.63 | K28: 0.69 | L28: 0.66 | M28: 1042 | Q28: 1 | R28: 0.72 | S28: 0.85 | T28: 0.78 | U28: 1188
A29: accuracy | D29: 0.65 | E29: 362 | I29: accuracy | L29: 0.63 | M29: 2000 | Q29: accuracy | T29: 0.72 | U29: 2000
A30: macro avg | B30: 0.65 | C30: 0.65 | D30: 0.65 | E30: 362 | I30: macro avg | J30: 0.63 | K30: 0.63 | L30: 0.63 | M30: 2000 | Q30: macro avg | R30: 0.71 | S30: 0.69 | T30: 0.69 | U30: 2000
A31: weighted avg | B31: 0.66 | C31: 0.65 | D31: 0.65 | E31: 362 | I31: weighted avg | J31: 0.63 | K31: 0.63 | L31: 0.63 | M31: 2000 | Q31: weighted avg | R31: 0.72 | S31: 0.72 | T31: 0.71 | U31: 2000
A33: ITA-ROCE-RandomForestClassifier | I33: EU-ROCE-RandomForestClassifier | Q33: USA-ROCE-RandomForestClassifier
B34: precision | C34: recall | D34: f1-score | E34: support | F34: confusion matrix | G34: roc-auc score | J34: precision | K34: recall | L34: f1-score | M34: support | N34: confusion matrix | O34: roc-auc score | R34: precision | S34: recall | T34: f1-score | U34: support | V34: confusion matrix | W34: roc-auc score
A35: 0 | B35: 0.6 | C35: 0.72 | D35: 0.65 | E35: 167 | F35: [[120 47] [ 80 115]] | G35: 0.65415323 | I35: 0 | J35: 0.61 | K35: 0.64 | L35: 0.62 | M35: 958 | N35: [[616 342] [402 640]] | O35: 0.62860486 | Q35: 0 | R35: 0.63 | S35: 0.57 | T35: 0.6 | U35: 812 | V35: [[464 348] [271 917]] | W35: 0.67165705
A36: 1 | B36: 0.71 | C36: 0.59 | D36: 0.64 | E36: 195 | I36: 1 | J36: 0.65 | K36: 0.61 | L36: 0.63 | M36: 1042 | Q36: 1 | R36: 0.72 | S36: 0.77 | T36: 0.75 | U36: 1188
A37: accuracy | D37: 0.65 | E37: 362 | I37: accuracy | L37: 0.63 | M37: 2000 | Q37: accuracy | T37: 0.69 | U37: 2000
A38: macro avg | B38: 0.65 | C38: 0.65 | D38: 0.65 | E38: 362 | I38: macro avg | J38: 0.63 | K38: 0.63 | L38: 0.63 | M38: 2000 | Q38: macro avg | R38: 0.68 | S38: 0.67 | T38: 0.67 | U38: 2000
A39: weighted avg | B39: 0.66 | C39: 0.65 | D39: 0.65 | E39: 362 | I39: weighted avg | J39: 0.63 | K39: 0.63 | L39: 0.63 | M39: 2000 | Q39: weighted avg | R39: 0.69 | S39: 0.69 | T39: 0.69 | U39: 2000
A41: ITA-ROCE-MPLClassifier | I41: EU-ROCE-MPLClassifier | Q41: USA-ROCE-MPLClassifier
B42: precision | C42: recall | D42: f1-score | E42: support | F42: confusion matrix | G42: roc-auc score | J42: precision | K42: recall | L42: f1-score | M42: support | N42: confusion matrix | O42: roc-auc score | R42: precision | S42: recall | T42: f1-score | U42: support | V42: confusion matrix | W42: roc-auc score
A43: 0 | B43: 0.49 | C43: 0.75 | D43: 0.59 | E43: 167 | F43: [[125 42] [131 64]] | G43: 0.53835406 | I43: 0 | J43: 0.49 | K43: 0.99 | L43: 0.65 | M43: 958 | N43: [[ 950 8] [1004 38]] | O43: 0.5140588 | Q43: 0 | R43: 0.5 | S43: 0 | T43: 0 | U43: 812 | V43: [[ 1 811] [ 1 1187]] | W43: 0.50019489
A44: 1 | B44: 0.6 | C44: 0.33 | D44: 0.43 | E44: 195 | I44: 1 | J44: 0.83 | K44: 0.04 | L44: 0.07 | M44: 1042 | Q44: 1 | R44: 0.59 | S44: 1 | T44: 0.75 | U44: 1188
A45: accuracy | D45: 0.52 | E45: 362 | I45: accuracy | L45: 0.49 | M45: 2000 | Q45: accuracy | T45: 0.59 | U45: 2000
...

Sheet median (1995-2023)
A1: ITA-ROE-GradientBoostingClassifier | I1: EU-ROE-GradientBoostingClassifier | Q1: USA-ROE-GradientBoostingClassifier
B2: precision | C2: recall | D2: f1-score | E2: support | F2: confusion matrix | G2: roc-auc score | J2: precision | K2: recall | L2: f1-score | M2: support | N2: confusion matrix | O2: roc-auc score | R2: precision | S2: recall | T2: f1-score | U2: support | V2: confusion matrix | W2: roc-auc score
A3: 0 | B3: 0.72 | C3: 0.58 | D3: 0.64 | E3: 196 | F3: [[114 82] [ 45 121]] | G3: 0.65527416 | I3: 0 | J3: 0.69 | K3: 0.62 | L3: 0.65 | M3: 1099 | N3: [[677 422] [298 603]] | O3: 0.64263547 | Q3: 0 | R3: 0.73 | S3: 0.52 | T3: 0.61 | U3: 991 | V3: [[516 475] [187 822]] | W3: 0.66767708
A4: 1 | B4: 0.6 | C4: 0.73 | D4: 0.66 | E4: 166 | I4: 1 | J4: 0.59 | K4: 0.67 | L4: 0.63 | M4: 901 | Q4: 1 | R4: 0.63 | S4: 0.81 | T4: 0.71 | U4: 1009
A5: accuracy | D5: 0.65 | E5: 362 | I5: accuracy | L5: 0.64 | M5: 2000 | Q5: accuracy | T5: 0.67 | U5: 2000
A6: macro avg | B6: 0.66 | C6: 0.66 | D6: 0.65 | E6: 362 | I6: macro avg | J6: 0.64 | K6: 0.64 | L6: 0.64 | M6: 2000 | Q6: macro avg | R6: 0.68 | S6: 0.67 | T6: 0.66 | U6: 2000
A7: weighted avg | B7: 0.66 | C7: 0.65 | D7: 0.65 | E7: 362 | I7: weighted avg | J7: 0.65 | K7: 0.64 | L7: 0.64 | M7: 2000 | Q7: weighted avg | R7: 0.68 | S7: 0.67 | T7: 0.66 | U7: 2000
A9: ITA-ROE-RandomForestClassifier | I9: EU-ROE-RandomForestClassifier | Q9: USA-ROE-RandomForestClassifier
B10: precision | C10: recall | D10: f1-score | E10: support | F10: confusion matrix | G10: roc-auc score | J10: precision | K10: recall | L10: f1-score | M10: support | N10: confusion matrix | O10: roc-auc score | R10: precision | S10: recall | T10: f1-score | U10: support | V10: confusion matrix | W10: roc-auc score
A11: 0 | B11: 0.66 | C11: 0.7 | D11: 0.68 | E11: 196 | F11: [[138 58] [ 70 96]] | G11: 0.64119744 | I11: 0 | J11: 0.69 | K11: 0.65 | L11: 0.67 | M11: 1099 | N11: [[714 385] [317 584]] | O11: 0.64892512 | Q11: 0 | R11: 0.69 | S11: 0.59 | T11: 0.64 | U11: 991 | V11: [[589 402] [263 746]] | W11: 0.66684751
A12: 1 | B12: 0.62 | C12: 0.58 | D12: 0.6 | E12: 166 | I12: 1 | J12: 0.6 | K12: 0.65 | L12: 0.62 | M12: 901 | Q12: 1 | R12: 0.65 | S12: 0.74 | T12: 0.69 | U12: 1009
A13: accuracy | D13: 0.65 | E13: 362 | I13: accuracy | L13: 0.65 | M13: 2000 | Q13: accuracy | T13: 0.67 | U13: 2000
A14: macro avg | B14: 0.64 | C14: 0.64 | D14: 0.64 | E14: 362 | I14: macro avg | J14: 0.65 | K14: 0.65 | L14: 0.65 | M14: 2000 | Q14: macro avg | R14: 0.67 | S14: 0.67 | T14: 0.67 | U14: 2000
A15: weighted avg | B15: 0.65 | C15: 0.65 | D15: 0.65 | E15: 362 | I15: weighted avg | J15: 0.65 | K15: 0.65 | L15: 0.65 | M15: 2000 | Q15: weighted avg | R15: 0.67 | S15: 0.67 | T15: 0.67 | U15: 2000
A17: ITA-ROE-MPLClassifier | I17: EU-ROE-MPLClassifier | Q17: USA-ROE-MPLClassifier
B18: precision | C18: recall | D18: f1-score | E18: support | F18: confusion matrix | G18: roc-auc score | J18: precision | K18: recall | L18: f1-score | M18: support | N18: confusion matrix | O18: roc-auc score | R18: precision | S18: recall | T18: f1-score | U18: support | V18: confusion matrix | W18: roc-auc score
A19: 0 | B19: 0.59 | C19: 0.85 | D19: 0.7 | E19: 196 | F19: [[166 30] [113 53]] | G19: 0.58310794 | I19: 0 | J19: 0.8 | K19: 0 | L19: 0.01 | M19: 1099 | N19: [[ 4 1095] [ 1 900]] | O19: 0.5012649 | Q19: 0 | R19: 0.63 | S19: 0.48 | T19: 0.55 | U19: 991 | V19: [[477 514] [280 729]] | W19: 0.60191476
A20: 1 | B20: 0.64 | C20: 0.32 | D20: 0.43 | E20: 166 | I20: 1 | J20: 0.45 | K20: 1 | L20: 0.62 | M20: 901 | Q20: 1 | R20: 0.59 | S20: 0.72 | T20: 0.65 | U20: 1009
A21: accuracy | D21: 0.6 | E21: 362 | I21: accuracy | L21: 0.45 | M21: 2000 | Q21: accuracy | T21: 0.6 | U21: 2000
A22: macro avg | B22: 0.62 | C22: 0.58 | D22: 0.56 | E22: 362 | I22: macro avg | J22: 0.63 | K22: 0.5 | L22: 0.31 | M22: 2000 | Q22: macro avg | R22: 0.61 | S22: 0.6 | T22: 0.6 | U22: 2000
A23: weighted avg | B23: 0.61 | C23: 0.6 | D23: 0.57 | E23: 362 | I23: weighted avg | J23: 0.64 | K23: 0.45 | L23: 0.28 | M23: 2000 | Q23: weighted avg | R23: 0.61 | S23: 0.6 | T23: 0.6 | U23: 2000
A25: ITA-ROCE-GradientBoostingClassifier | I25: EU-ROCE-GradientBoostingClassifier | Q25: USA-ROCE-GradientBoostingClassifier
B26: precision | C26: recall | D26: f1-score | E26: support | F26: confusion matrix | G26: roc-auc score | J26: precision | K26: recall | L26: f1-score | M26: support | N26: confusion matrix | O26: roc-auc score | R26: precision | S26: recall | T26: f1-score | U26: support | V26: confusion matrix | W26: roc-auc score
A27: 0 | B27: 0.61 | C27: 0.68 | D27: 0.64 | E27: 167 | F27: [[113 54] [ 72 123]] | G27: 0.65370797 | I27: 0 | J27: 0.63 | K27: 0.57 | L27: 0.6 | M27: 958 | N27: [[549 409] [326 716]] | O27: 0.6301045 | Q27: 0 | R27: 0.7 | S27: 0.49 | T27: 0.58 | U27: 812 | V27: [[ 400 412] [ 169 1019]] | W27: 0.67517747
A28: 1 | B28: 0.69 | C28: 0.63 | D28: 0.66 | E28: 195 | I28: 1 | J28: 0.64 | K28: 0.69 | L28: 0.66 | M28: 1042 | Q28: 1 | R28: 0.71 | S28: 0.86 | T28: 0.78 | U28: 1188
A29: accuracy | D29: 0.65 | E29: 362 | I29: accuracy | L29: 0.63 | M29: 2000 | Q29: accuracy | T29: 0.71 | U29: 2000
A30: macro avg | B30: 0.65 | C30: 0.65 | D30: 0.65 | E30: 362 | I30: macro avg | J30: 0.63 | K30: 0.63 | L30: 0.63 | M30: 2000 | Q30: macro avg | R30: 0.71 | S30: 0.68 | T30: 0.68 | U30: 2000
A31: weighted avg | B31: 0.66 | C31: 0.65 | D31: 0.65 | E31: 362 | I31: weighted avg | J31: 0.63 | K31: 0.63 | L31: 0.63 | M31: 2000 | Q31: weighted avg | R31: 0.71 | S31: 0.71 | T31: 0.7 | U31: 2000
A33: ITA-ROCE-RandomForestClassifier | I33: EU-ROCE-RandomForestClassifier | Q33: USA-ROCE-RandomForestClassifier
B34: precision | C34: recall | D34: f1-score | E34: support | F34: confusion matrix | G34: roc-auc score | J34: precision | K34: recall | L34: f1-score | M34: support | N34: confusion matrix | O34: roc-auc score | R34: precision | S34: recall | T34: f1-score | U34: support | V34: confusion matrix | W34: roc-auc score
A35: 0 | B35: 0.6 | C35: 0.74 | D35: 0.66 | E35: 167 | F35: [[123 44] [ 82 113]] | G35: 0.65800706 | I35: 0 | J35: 0.61 | K35: 0.63 | L35: 0.62 | M35: 958 | N35: [[608 350] [391 651]] | O35: 0.6297078 | Q35: 0 | R35: 0.66 | S35: 0.58 | T35: 0.62 | U35: 812 | V35: [[474 338] [247 941]] | W35: 0.68791569
A36: 1 | B36: 0.72 | C36: 0.58 | D36: 0.64 | E36: 195 | I36: 1 | J36: 0.65 | K36: 0.62 | L36: 0.64 | M36: 1042 | Q36: 1 | R36: 0.74 | S36: 0.79 | T36: 0.76 | U36: 1188
A37: accuracy | D37: 0.65 | E37: 362 | I37: accuracy | L37: 0.63 | M37: 2000 | Q37: accuracy | T37: 0.71 | U37: 2000
A38: macro avg | B38: 0.66 | C38: 0.66 | D38: 0.65 | E38: 362 | I38: macro avg | J38: 0.63 | K38: 0.63 | L38: 0.63 | M38: 2000 | Q38: macro avg | R38: 0.7 | S38: 0.69 | T38: 0.69 | U38: 2000
A39: weighted avg | B39: 0.66 | C39: 0.65 | D39: 0.65 | E39: 362 | I39: weighted avg | J39: 0.63 | K39: 0.63 | L39: 0.63 | M39: 2000 | Q39: weighted avg | R39: 0.7 | S39: 0.71 | T39: 0.7 | U39: 2000
A41: ITA-ROCE-MPLClassifier | I41: EU-ROCE-MPLClassifier | Q41: USA-ROCE-MPLClassifier
B42: precision | C42: recall | D42: f1-score | E42: support | F42: confusion matrix | G42: roc-auc score | J42: precision | K42: recall | L42: f1-score | M42: support | N42: confusion matrix | O42: roc-auc score | R42: precision | S42: recall | T42: f1-score | U42: support | V42: confusion matrix | W42: roc-auc score
A43: 0 | B43: 0.52 | C43: 0.86 | D43: 0.65 | E43: 167 | F43: [[144 23] [135 60]] | G43: 0.58498388 | I43: 0 | J43: 0.57 | K43: 0.63 | L43: 0.6 | M43: 958 | N43: [[599 359] [451 591]] | O43: 0.59621973 | Q43: 0 | R43: 0.68 | S43: 0.17 | T43: 0.28 | U43: 812 | V43: [[ 142 670] [ 67 1121]] | W43: 0.55923977
A44: 1 | B44: 0.72 | C44: 0.31 | D44: 0.43 | E44: 195 | I44: 1 | J44: 0.62 | K44: 0.57 | L44: 0.59 | M44: 1042 | Q44: 1 | R44: 0.63 | S44: 0.94 | T44: 0.75 | U44: 1188
A45: accuracy | D45: 0.56 | E45: 362 | I45: accuracy | L45: 0.59 | M45: 2000 | Q45: accuracy | T45: 0.63 | U45: 2000
...

Sheet results (1995-2023)
A1: ROC-AUC | B1: ROE | D1: ROCE | F1: Utile Netto
A2: ITA | B2: =MAX('zero (1995-2023)'!G3,'zero (1995-2023)'!G11,'zero (1995-2023)'!G19,'mean (1995-2023)'!G3,'mean (1995-2023)'!G11,'mean (1995-2023)'!G19,'median (1995-2023)'!G3,'median (1995-2023)'!G11,'median (1995-2023)'!G19,) -> 0.65807106 | C2: GradientBoostingClassifier - ZERO | D2: =MAX('zero (1995-2023)'!G27,'zero (1995-2023)'!G35,'zero (1995-2023)'!G43,'mean (1995-2023)'!G27,'mean (1995-2023)'!G35,'mean (1995-2023)'!G43,'median (1995-2023)'!G27,'median (1995-2023)'!G35,'median (1995-2023)'!G43) -> 0.65800706 | E2: RandomForestClassifier - MEDIAN | F2: =MAX('zero (1995-2023)'!G51,'zero (1995-2023)'!G59,'zero (1995-2023)'!G67,'mean (1995-2023)'!G51,'mean (1995-2023)'!G59,'mean (1995-2023)'!G67,'median (1995-2023)'!G51,'median (1995-2023)'!G59,'median (1995-2023)'!G67) -> 0.60508714 | G2: RandomForestClassifier - MEDIAN
A3: EU | B3: =MAX('zero (1995-2023)'!O3,'zero (1995-2023)'!O11,'zero (1995-2023)'!O19,'mean (1995-2023)'!O3,'mean (1995-2023)'!O11,'mean (1995-2023)'!O19,'median (1995-2023)'!O3,'median (1995-2023)'!O11,'median (1995-2023)'!O19) -> 0.64892512 | C3: RandomForestClassifier - MEDIAN | D3: =MAX('zero (1995-2023)'!O27,'zero (1995-2023)'!O35,'zero (1995-2023)'!O43,'mean (1995-2023)'!O27,'mean (1995-2023)'!O35,'mean (1995-2023)'!O43,'median (1995-2023)'!O27,'median (1995-2023)'!O35,'median (1995-2023)'!O43) -> 0.64456601 | E3: RandomForestClassifier - ZERO | F3: =MAX('zero (1995-2023)'!O51,'zero (1995-2023)'!O59,'zero (1995-2023)'!O67,'mean (1995-2023)'!O51,'mean (1995-2023)'!O59,'mean (1995-2023)'!O67,'median (1995-2023)'!O51,'median (1995-2023)'!O59,'median (1995-2023)'!O67) -> 0.59751686 | G3: GradientBoostingClassifier - MEDIAN
A4: USA | B4: =MAX('zero (1995-2023)'!W3,'zero (1995-2023)'!W11,'zero (1995-2023)'!W19,'mean (1995-2023)'!W3,'mean (1995-2023)'!W11,'mean (1995-2023)'!W19,'median (1995-2023)'!W3,'median (1995-2023)'!W11,'median (1995-2023)'!W19) -> 0.66882968 | C4: RandomForestClassifier - MEAN | D4: =MAX('zero (1995-2023)'!W27,'zero (1995-2023)'!W35,'zero (1995-2023)'!W43,'mean (1995-2023)'!W27,'mean (1995-2023)'!W35,'mean (1995-2023)'!W43,'median (1995-2023)'!W27,'median (1995-2023)'!W35,'median (1995-2023)'!W43) -> 0.68791569 | E4: RandomForestClassifier - MEDIAN | F4: =MAX('zero (1995-2023)'!W51,'zero (1995-2023)'!W59,'zero (1995-2023)'!W67,'mean (1995-2023)'!W51,'mean (1995-2023)'!W59,'mean (1995-2023)'!W67,'median (1995-2023)'!W51,'median (1995-2023)'!W59,'median (1995-2023)'!W67) -> 0.60922246 | G4: GradientBoostingClassifier - MEAN
A6: ACCURACY | B6: ROE | D6: ROCE | F6: Utile Netto
A7: ITA | B7: =MAX('zero (1995-2023)'!D5,'zero (1995-2023)'!D13,'zero (1995-2023)'!D21,'mean (1995-2023)'!D5,'mean (1995-2023)'!D13,'mean (1995-2023)'!D21,'median (1995-2023)'!D5,'median (1995-2023)'!D13,'median (1995-2023)'!D21) -> 0.65 | C7: GradientBoostingClassifier - ZERO; GradientBoostingClassifier - MEAN; RandomForestClassifier - MEAN; GradientBoostingClassifier - MEDIAN; RandomForestClassifier - MEDIAN; | D7: =MAX('zero (1995-2023)'!D29,'zero (1995-2023)'!D37,'zero (1995-2023)'!D45,'mean (1995-2023)'!D29,'mean (1995-2023)'!D37,'mean (1995-2023)'!D45,'median (1995-2023)'!D29,'median (1995-2023)'!D37,'median (1995-2023)'!D45) -> 0.66 | E7: GradientBoostingClassifier - ZERO | F7: =MAX('zero (1995-2023)'!D53,'zero (1995-2023)'!D61,'zero (1995-2023)'!D69,'mean (1995-2023)'!D53,'mean (1995-2023)'!D61,'mean (1995-2023)'!D69,'median (1995-2023)'!D53,'median (1995-2023)'!D61,'median (1995-2023)'!D69) -> 0.61 | G7: GradientBoostingClassifier - ZERO; RandomForestClassifier - MEDIAN;
A8: EU | B8: =MAX('zero (1995-2023)'!L5,'zero (1995-2023)'!L13,'zero (1995-2023)'!L21,'mean (1995-2023)'!L5,'mean (1995-2023)'!L13,'mean (1995-2023)'!L21,'median (1995-2023)'!L5,'median (1995-2023)'!L13,'median (1995-2023)'!L21) -> 0.65 | C8: RandomForestClassifier - MEAN; RandomForestClassifier - MEDIAN; | D8: =MAX('zero (1995-2023)'!L29,'zero (1995-2023)'!L37,'zero (1995-2023)'!L45,'mean (1995-2023)'!L29,'mean (1995-2023)'!L37,'mean (1995-2023)'!L45,'median (1995-2023)'!L29,'median (1995-2023)'!L37,'median (1995-2023)'!L45) -> 0.64 | E8: RandomForestClassifier - ZERO | F8: =MAX('zero (1995-2023)'!L53,'zero (1995-2023)'!L61,'zero (1995-2023)'!L69,'mean (1995-2023)'!L53,'mean (1995-2023)'!L61,'mean (1995-2023)'!L69,'median (1995-2023)'!L53,'median (1995-2023)'!L61,'median (1995-2023)'!L69) -> 0.61 | G8: GradientBoostingClassifier - MEAN; GradientBoostingClassifier - MEDIAN;
A9: USA | B9: =MAX('zero (1995-2023)'!T5,'zero (1995-2023)'!T13,'zero (1995-2023)'!T21,'mean (1995-2023)'!T5,'mean (1995-2023)'!T13,'mean (1995-2023)'!T21,'median (1995-2023)'!T5,'median (1995-2023)'!T13,'median (1995-2023)'!T21) -> 0.67 | C9: GradientBoostingClassifier - ZERO; RandomForestClassifier - ZERO; GradientBoostingClassifier - MEAN; RandomForestClassifier - MEAN; GradientBoostingClassifier - MEDIAN; RandomForestClassifier - MEDIAN; | D9: =MAX('zero (1995-2023)'!T29,'zero (1995-2023)'!T37,'zero (1995-2023)'!T45,'mean (1995-2023)'!T29,'mean (1995-2023)'!T37,'mean (1995-2023)'!T45,'median (1995-2023)'!T29,'median (1995-2023)'!T37,'median (1995-2023)'!T45) -> 0.72 | E9: GradientBoostingClassifier - ZERO | F9: =MAX('zero (1995-2023)'!T53,'zero (1995-2023)'!T61,'zero (1995-2023)'!T69,'mean (1995-2023)'!T53,'mean (1995-2023)'!T61,'mean (1995-2023)'!T69,'median (1995-2023)'!T53,'median (1995-2023)'!T61,'median (1995-2023)'!T69) -> 0.64 | G9: GradientBoostingClassifier - ZERO; GradientBoostingClassifier - MEAN;

Sheet zero (1998-2023)
A1: ITA-ROE-GradientBoostingClassifier | I1: EU-ROE-GradientBoostingClassifier | Q1: USA-ROE-GradientBoostingClassifier
B2: precision | C2: recall | D2: f1-score | E2: support | F2: confusion matrix | G2: roc-auc score | J2: precision | K2: recall | L2: f1-score | M2: support | N2: confusion matrix | O2: roc-auc score | R2: precision | S2: recall | T2: f1-score | U2: support | V2: confusion matrix | W2: roc-auc score
A3: 0 | B3: 0.71 | C3: 0.68 | D3: 0.69 | E3: 196 | F3: [[134 62] [ 56 110]] | G3: 0.67316204 | I3: 0 | J3: 0.71 | K3: 0.6 | L3: 0.65 | M3: 1099 | N3: [[663 436] [276 625]] | O3: 0.6484747 | Q3: 0 | R3: 0.73 | S3: 0.56 | T3: 0.64 | U3: 991 | V3: [[555 436] [201 808]] | W3: 0.68041661
A4: 1 | B4: 0.64 | C4: 0.66 | D4: 0.65 | E4: 166 | I4: 1 | J4: 0.59 | K4: 0.69 | L4: 0.64 | M4: 901 | Q4: 1 | R4: 0.65 | S4: 0.8 | T4: 0.72 | U4: 1009
A5: accuracy | D5: 0.67 | E5: 362 | I5: accuracy | L5: 0.64 | M5: 2000 | Q5: accuracy | T5: 0.68 | U5: 2000
A6: macro avg | B6: 0.67 | C6: 0.67 | D6: 0.67 | E6: 362 | I6: macro avg | J6: 0.65 | K6: 0.65 | L6: 0.64 | M6: 2000 | Q6: macro avg | R6: 0.69 | S6: 0.68 | T6: 0.68 | U6: 2000
A7: weighted avg | B7: 0.68 | C7: 0.67 | D7: 0.67 | E7: 362 | I7: weighted avg | J7: 0.65 | K7: 0.64 | L7: 0.64 | M7: 2000 | Q7: weighted avg | R7: 0.69 | S7: 0.68 | T7: 0.68 | U7: 2000
A9: ITA-ROE-RandomForestClassifier | I9: EU-ROE-RandomForestClassifier | Q9: USA-ROE-RandomForestClassifier
B10: precision | C10: recall | D10: f1-score | E10: support | F10: confusion matrix | G10: roc-auc score | J10: precision | K10: recall | L10: f1-score | M10: support | N10: confusion matrix | O10: roc-auc score | R10: precision | S10: recall | T10: f1-score | U10: support | V10: confusion matrix | W10: roc-auc score
A11: 0 | B11: 0.65 | C11: 0.69 | D11: 0.67 | E11: 196 | F11: [[136 60] [ 72 94]] | G11: 0.63007131 | I11: 0 | J11: 0.68 | K11: 0.64 | L11: 0.66 | M11: 1099 | N11: [[704 395] [324 577]] | O11: 0.64049095 | Q11: 0 | R11: 0.69 | S11: 0.58 | T11: 0.63 | U11: 991 | V11: [[575 416] [259 750]] | W11: 0.6617661
A12: 1 | B12: 0.61 | C12: 0.57 | D12: 0.59 | E12: 166 | I12: 1 | J12: 0.59 | K12: 0.64 | L12: 0.62 | M12: 901 | Q12: 1 | R12: 0.64 | S12: 0.74 | T12: 0.69 | U12: 1009
A13: accuracy | D13: 0.64 | E13: 362 | I13: accuracy | L13: 0.64 | M13: 2000 | Q13: accuracy | T13: 0.66 | U13: 2000
A14: macro avg | B14: 0.63 | C14: 0.63 | D14: 0.63 | E14: 362 | I14: macro avg | J14: 0.64 | K14: 0.64 | L14: 0.64 | M14: 2000 | Q14: macro avg | R14: 0.67 | S14: 0.66 | T14: 0.66 | U14: 2000
A15: weighted avg | B15: 0.63 | C15: 0.64 | D15: 0.63 | E15: 362 | I15: weighted avg | J15: 0.64 | K15: 0.64 | L15: 0.64 | M15: 2000 | Q15: weighted avg | R15: 0.67 | S15: 0.66 | T15: 0.66 | U15: 2000
A17: ITA-ROE-MPLClassifier | I17: EU-ROE-MPLClassifier | Q17: USA-ROE-MPLClassifier
B18: precision | C18: recall | D18: f1-score | E18: support | F18: confusion matrix | G18: roc-auc score | J18: precision | K18: recall | L18: f1-score | M18: support | N18: confusion matrix | O18: roc-auc score | R18: precision | S18: recall | T18: f1-score | U18: support | V18: confusion matrix | W18: roc-auc score
A19: 0 | B19: 0.59 | C19: 0.52 | D19: 0.55 | E19: 196 | F19: [[102 94] [ 72 94]] | G19: 0.54333661 | I19: 0 | J19: 0.6 | K19: 0.92 | L19: 0.73 | M19: 1099 | N19: [[1014 85] [ 681 220]] | O19: 0.58341505 | Q19: 0 | R19: 0.67 | S19: 0 | T19: 0 | U19: 991 | V19: [[ 2 989] [ 1 1008]] | W19: 0.50051354
A20: 1 | B20: 0.5 | C20: 0.57 | D20: 0.53 | E20: 166 | I20: 1 | J20: 0.72 | K20: 0.24 | L20: 0.36 | M20: 901 | Q20: 1 | R20: 0.5 | S20: 1 | T20: 0.67 | U20: 1009
A21: accuracy | D21: 0.54 | E21: 362 | I21: accuracy | L21: 0.62 | M21: 2000 | Q21: accuracy | T21: 0.51 | U21: 2000
A22: macro avg | B22: 0.54 | C22: 0.54 | D22: 0.54 | E22: 362 | I22: macro avg | J22: 0.66 | K22: 0.58 | L22: 0.55 | M22: 2000 | Q22: macro avg | R22: 0.59 | S22: 0.5 | T22: 0.34 | U22: 2000
A23: weighted avg | B23: 0.55 | C23: 0.54 | D23: 0.54 | E23: 362 | I23: weighted avg | J23: 0.65 | K23: 0.62 | L23: 0.56 | M23: 2000 | Q23: weighted avg | R23: 0.58 | S23: 0.51 | T23: 0.34 | U23: 2000
A25: ITA-ROCE-GradientBoostingClassifier | I25: EU-ROCE-GradientBoostingClassifier | Q25: USA-ROCE-GradientBoostingClassifier
B26: precision | C26: recall | D26: f1-score | E26: support | F26: confusion matrix | G26: roc-auc score | J26: precision | K26: recall | L26: f1-score | M26: support | N26: confusion matrix | O26: roc-auc score | R26: precision | S26: recall | T26: f1-score | U26: support | V26: confusion matrix | W26: roc-auc score
A27: 0 | B27: 0.63 | C27: 0.68 | D27: 0.65 | E27: 167 | F27: [[113 54] [ 67 128]] | G27: 0.66652848 | I27: 0 | J27: 0.62 | K27: 0.59 | L27: 0.6 | M27: 958 | N27: [[564 394] [344 698]] | O27: 0.62929608 | Q27: 0 | R27: 0.7 | S27: 0.48 | T27: 0.57 | U27: 812 | V27: [[ 393 419] [ 166 1022]] | W27: 0.67212975
A28: 1 | B28: 0.7 | C28: 0.66 | D28: 0.68 | E28: 195 | I28: 1 | J28: 0.64 | K28: 0.67 | L28: 0.65 | M28: 1042 | Q28: 1 | R28: 0.71 | S28: 0.86 | T28: 0.78 | U28: 1188
A29: accuracy | D29: 0.67 | E29: 362 | I29: accuracy | L29: 0.63 | M29: 2000 | Q29: accuracy | T29: 0.71 | U29: 2000
A30: macro avg | B30: 0.67 | C30: 0.67 | D30: 0.67 | E30: 362 | I30: macro avg | J30: 0.63 | K30: 0.63 | L30: 0.63 | M30: 2000 | Q30: macro avg | R30: 0.71 | S30: 0.67 | T30: 0.68 | U30: 2000
A31: weighted avg | B31: 0.67 | C31: 0.67 | D31: 0.67 | E31: 362 | I31: weighted avg | J31: 0.63 | K31: 0.63 | L31: 0.63 | M31: 2000 | Q31: weighted avg | R31: 0.71 | S31: 0.71 | T31: 0.69 | U31: 2000
A33: ITA-ROCE-RandomForestClassifier | I33: EU-ROCE-RandomForestClassifier | Q33: USA-ROCE-RandomForestClassifier
B34: precision | C34: recall | D34: f1-score | E34: support | F34: confusion matrix | G34: roc-auc score | J34: precision | K34: recall | L34: f1-score | M34: support | N34: confusion matrix | O34: roc-auc score | R34: precision | S34: recall | T34: f1-score | U34: support | V34: confusion matrix | W34: roc-auc score
A35: 0 | B35: 0.56 | C35: 0.71 | D35: 0.63 | E35: 167 | F35: [[119 48] [ 93 102]] | G35: 0.61782589 | I35: 0 | J35: 0.61 | K35: 0.61 | L35: 0.61 | M35: 958 | N35: [[589 369] [374 668]] | O35: 0.6279487 | Q35: 0 | R35: 0.65 | S35: 0.59 | T35: 0.61 | U35: 812 | V35: [[476 336] [260 928]] | W35: 0.68367584
A36: 1 | B36: 0.68 | C36: 0.52 | D36: 0.59 | E36: 195 | I36: 1 | J36: 0.64 | K36: 0.64 | L36: 0.64 | M36: 1042 | Q36: 1 | R36: 0.73 | S36: 0.78 | T36: 0.76 | U36: 1188
A37: accuracy | D37: 0.61 | E37: 362 | I37: accuracy | L37: 0.63 | M37: 2000 | Q37: accuracy | T37: 0.7 | U37: 2000
A38: macro avg | B38: 0.62 | C38: 0.62 | D38: 0.61 | E38: 362 | I38: macro avg | J38: 0.63 | K38: 0.63 | L38: 0.63 | M38: 2000 | Q38: macro avg | R38: 0.69 | S38: 0.68 | T38: 0.69 | U38: 2000
A39: weighted avg | B39: 0.63 | C39: 0.61 | D39: 0.61 | E39: 362 | I39: weighted avg | J39: 0.63 | K39: 0.63 | L39: 0.63 | M39: 2000 | Q39: weighted avg | R39: 0.7 | S39: 0.7 | T39: 0.7 | U39: 2000
A41: ITA-ROCE-MPLClassifier | I41: EU-ROCE-MPLClassifier | Q41: USA-ROCE-MPLClassifier
B42: precision | C42: recall | D42: f1-score | E42: support | F42: confusion matrix | G42: roc-auc score | J42: precision | K42: recall | L42: f1-score | M42: support | N42: confusion matrix | O42: roc-auc score | R42: precision | S42: recall | T42: f1-score | U42: support | V42: confusion matrix | W42: roc-auc score
A43: 0 | B43: 0.52 | C43: 0.8 | D43: 0.63 | E43: 167 | F43: [[133 34] [125 70]] | G43: 0.57769077 | I43: 0 | J43: 0.48 | K43: 0.99 | L43: 0.65 | M43: 958 | N43: [[ 950 8] [1009 33]] | O43: 0.51165957 | Q43: 0 | R43: 0.59 | S43: 0.17 | T43: 0.26 | U43: 812 | V43: [[ 138 674] [ 96 1092]] | W43: 0.54457133
A44: 1 | B44: 0.67 | C44: 0.36 | D44: 0.47 | E44: 195 | I44: 1 | J44: 0.8 | K44: 0.03 | L44: 0.06 | M44: 1042 | Q44: 1 | R44: 0.62 | S44: 0.92 | T44: 0.74 | U44: 1188
A45: accuracy | D45: 0.56 | E45: 362 | I45: accuracy | L45: 0.49 | M45: 2000 | Q45: accuracy | T45: 0.61 | U45: 2000
...

Sheet mean (1998-2023)
A1: ITA-ROE-GradientBoostingClassifier | I1: EU-ROE-GradientBoostingClassifier | Q1: USA-ROE-GradientBoostingClassifier
B2: precision | C2: recall | D2: f1-score | E2: support | F2: confusion matrix | G2: roc-auc score | J2: precision | K2: recall | L2: f1-score | M2: support | N2: confusion matrix | O2: roc-auc score | R2: precision | S2: recall | T2: f1-score | U2: support | V2: confusion matrix | W2: roc-auc score
A3: 0 | B3: 0.71 | C3: 0.65 | D3: 0.68 | E3: 196 | F3: [[127 69] [ 51 115]] | G3: 0.67036513 | I3: 0 | J3: 0.69 | K3: 0.63 | L3: 0.66 | M3: 1099 | N3: [[694 405] [312 589]] | O3: 0.64260063 | Q3: 0 | R3: 0.74 | S3: 0.53 | T3: 0.62 | U3: 991 | V3: [[527 464] [184 825]] | W3: 0.67471365
A4: 1 | B4: 0.62 | C4: 0.69 | D4: 0.66 | E4: 166 | I4: 1 | J4: 0.59 | K4: 0.65 | L4: 0.62 | M4: 901 | Q4: 1 | R4: 0.64 | S4: 0.82 | T4: 0.72 | U4: 1009
A5: accuracy | D5: 0.67 | E5: 362 | I5: accuracy | L5: 0.64 | M5: 2000 | Q5: accuracy | T5: 0.68 | U5: 2000
A6: macro avg | B6: 0.67 | C6: 0.67 | D6: 0.67 | E6: 362 | I6: macro avg | J6: 0.64 | K6: 0.64 | L6: 0.64 | M6: 2000 | Q6: macro avg | R6: 0.69 | S6: 0.67 | T6: 0.67 | U6: 2000
A7: weighted avg | B7: 0.67 | C7: 0.67 | D7: 0.67 | E7: 362 | I7: weighted avg | J7: 0.65 | K7: 0.64 | L7: 0.64 | M7: 2000 | Q7: weighted avg | R7: 0.69 | S7: 0.68 | T7: 0.67 | U7: 2000
A9: ITA-ROE-RandomForestClassifier | I9: EU-ROE-RandomForestClassifier | Q9: USA-ROE-RandomForestClassifier
B10: precision | C10: recall | D10: f1-score | E10: support | F10: confusion matrix | G10: roc-auc score | J10: precision | K10: recall | L10: f1-score | M10: support | N10: confusion matrix | O10: roc-auc score | R10: precision | S10: recall | T10: f1-score | U10: support | V10: confusion matrix | W10: roc-auc score
A11: 0 | B11: 0.65 | C11: 0.7 | D11: 0.67 | E11: 196 | F11: [[137 59] [ 75 91]] | G11: 0.62358618 | I11: 0 | J11: 0.68 | K11: 0.65 | L11: 0.66 | M11: 1099 | N11: [[709 390] [329 572]] | O11: 0.63999105 | Q11: 0 | R11: 0.69 | S11: 0.58 | T11: 0.63 | U11: 991 | V11: [[572 419] [257 752]] | W11: 0.66124356
A12: 1 | B12: 0.61 | C12: 0.55 | D12: 0.58 | E12: 166 | I12: 1 | J12: 0.59 | K12: 0.63 | L12: 0.61 | M12: 901 | Q12: 1 | R12: 0.64 | S12: 0.75 | T12: 0.69 | U12: 1009
A13: accuracy | D13: 0.63 | E13: 362 | I13: accuracy | L13: 0.64 | M13: 2000 | Q13: accuracy | T13: 0.66 | U13: 2000
A14: macro avg | B14: 0.63 | C14: 0.62 | D14: 0.62 | E14: 362 | I14: macro avg | J14: 0.64 | K14: 0.64 | L14: 0.64 | M14: 2000 | Q14: macro avg | R14: 0.67 | S14: 0.66 | T14: 0.66 | U14: 2000
A15: weighted avg | B15: 0.63 | C15: 0.63 | D15: 0.63 | E15: 362 | I15: weighted avg | J15: 0.64 | K15: 0.64 | L15: 0.64 | M15: 2000 | Q15: weighted avg | R15: 0.67 | S15: 0.66 | T15: 0.66 | U15: 2000
A17: ITA-ROE-MPLClassifier | I17: EU-ROE-MPLClassifier | Q17: USA-ROE-MPLClassifier
B18: precision | C18: recall | D18: f1-score | E18: support | F18: confusion matrix | G18: roc-auc score | J18: precision | K18: recall | L18: f1-score | M18: support | N18: confusion matrix | O18: roc-auc score | R18: precision | S18: recall | T18: f1-score | U18: support | V18: confusion matrix | W18: roc-auc score
A19: 0 | B19: 0.59 | C19: 0.9 | D19: 0.71 | E19: 196 | F19: [[176 20] [124 42]] | G19: 0.57548562 | I19: 0 | J19: 0.62 | K19: 0.72 | L19: 0.67 | M19: 1099 | N19: [[792 307] [482 419]] | O19: 0.59284699 | Q19: 0 | R19: 0.67 | S19: 0 | T19: 0 | U19: 991 | V19: [[ 2 989] [ 1 1008]] | W19: 0.50051354
A20: 1 | B20: 0.68 | C20: 0.25 | D20: 0.37 | E20: 166 | I20: 1 | J20: 0.58 | K20: 0.47 | L20: 0.52 | M20: 901 | Q20: 1 | R20: 0.5 | S20: 1 | T20: 0.67 | U20: 1009
A21: accuracy | D21: 0.6 | E21: 362 | I21: accuracy | L21: 0.61 | M21: 2000 | Q21: accuracy | T21: 0.51 | U21: 2000
A22: macro avg | B22: 0.63 | C22: 0.58 | D22: 0.54 | E22: 362 | I22: macro avg | J22: 0.6 | K22: 0.59 | L22: 0.59 | M22: 2000 | Q22: macro avg | R22: 0.59 | S22: 0.5 | T22: 0.34 | U22: 2000
A23: weighted avg | B23: 0.63 | C23: 0.6 | D23: 0.55 | E23: 362 | I23: weighted avg | J23: 0.6 | K23: 0.61 | L23: 0.6 | M23: 2000 | Q23: weighted avg | R23: 0.58 | S23: 0.51 | T23: 0.34 | U23: 2000
A25: ITA-ROCE-GradientBoostingClassifier | I25: EU-ROCE-GradientBoostingClassifier | Q25: USA-ROCE-GradientBoostingClassifier
B26: precision | C26: recall | D26: f1-score | E26: support | F26: confusion matrix | G26: roc-auc score | J26: precision | K26: recall | L26: f1-score | M26: support | N26: confusion matrix | O26: roc-auc score | R26: precision | S26: recall | T26: f1-score | U26: support | V26: confusion matrix | W26: roc-auc score
A27: 0 | B27: 0.63 | C27: 0.64 | D27: 0.64 | E27: 167 | F27: [[107 60] [ 62 133]] | G27: 0.66138492 | I27: 0 | J27: 0.63 | K27: 0.55 | L27: 0.59 | M27: 958 | N27: [[525 433] [304 738]] | O27: 0.62813503 | Q27: 0 | R27: 0.69 | S27: 0.51 | T27: 0.59 | U27: 812 | V27: [[414 398] [189 999]] | W27: 0.67538065
A28: 1 | B28: 0.69 | C28: 0.68 | D28: 0.69 | E28: 195 | I28: 1 | J28: 0.63 | K28: 0.71 | L28: 0.67 | M28: 1042 | Q28: 1 | R28: 0.72 | S28: 0.84 | T28: 0.77 | U28: 1188
A29: accuracy | D29: 0.66 | E29: 362 | I29: accuracy | L29: 0.63 | M29: 2000 | Q29: accuracy | T29: 0.71 | U29: 2000
A30: macro avg | B30: 0.66 | C30: 0.66 | D30: 0.66 | E30: 362 | I30: macro avg | J30: 0.63 | K30: 0.63 | L30: 0.63 | M30: 2000 | Q30: macro avg | R30: 0.7 | S30: 0.68 | T30: 0.68 | U30: 2000
A31: weighted avg | B31: 0.66 | C31: 0.66 | D31: 0.66 | E31: 362 | I31: weighted avg | J31: 0.63 | K31: 0.63 | L31: 0.63 | M31: 2000 | Q31: weighted avg | R31: 0.7 | S31: 0.71 | T31: 0.7 | U31: 2000
A33: ITA-ROCE-RandomForestClassifier | I33: EU-ROCE-RandomForestClassifier | Q33: USA-ROCE-RandomForestClassifier
B34: precision | C34: recall | D34: f1-score | E34: support | F34: confusion matrix | G34: roc-auc score | J34: precision | K34: recall | L34: f1-score | M34: support | N34: confusion matrix | O34: roc-auc score | R34: precision | S34: recall | T34: f1-score | U34: support | V34: confusion matrix | W34: roc-auc score
A35: 0 | B35: 0.56 | C35: 0.69 | D35: 0.62 | E35: 167 | F35: [[115 52] [ 90 105]] | G35: 0.61354215 | I35: 0 | J35: 0.61 | K35: 0.64 | L35: 0.63 | M35: 958 | N35: [[615 343] [385 657]] | O35: 0.63624033 | Q35: 0 | R35: 0.63 | S35: 0.57 | T35: 0.6 | U35: 812 | V35: [[463 349] [273 915]] | W35: 0.67019953
A36: 1 | B36: 0.67 | C36: 0.54 | D36: 0.6 | E36: 195 | I36: 1 | J36: 0.66 | K36: 0.63 | L36: 0.64 | M36: 1042 | Q36: 1 | R36: 0.72 | S36: 0.77 | T36: 0.75 | U36: 1188
A37: accuracy | D37: 0.61 | E37: 362 | I37: accuracy | L37: 0.64 | M37: 2000 | Q37: accuracy | T37: 0.69 | U37: 2000
A38: macro avg | B38: 0.61 | C38: 0.61 | D38: 0.61 | E38: 362 | I38: macro avg | J38: 0.64 | K38: 0.64 | L38: 0.64 | M38: 2000 | Q38: macro avg | R38: 0.68 | S38: 0.67 | T38: 0.67 | U38: 2000
A39: weighted avg | B39: 0.62 | C39: 0.61 | D39: 0.61 | E39: 362 | I39: weighted avg | J39: 0.64 | K39: 0.64 | L39: 0.64 | M39: 2000 | Q39: weighted avg | R39: 0.69 | S39: 0.69 | T39: 0.69 | U39: 2000
A41: ITA-ROCE-MPLClassifier | I41: EU-ROCE-MPLClassifier | Q41: USA-ROCE-MPLClassifier
B42: precision | C42: recall | D42: f1-score | E42: support | F42: confusion matrix | G42: roc-auc score | J42: precision | K42: recall | L42: f1-score | M42: support | N42: confusion matrix | O42: roc-auc score | R42: precision | S42: recall | T42: f1-score | U42: support | V42: confusion matrix | W42: roc-auc score
A43: 0 | B43: 0.5 | C43: 0.57 | D43: 0.53 | E43: 167 | F43: [[95 72] [96 99]] | G43: 0.53827729 | I43: 0 | J43: 0.53 | K43: 0.84 | L43: 0.65 | M43: 958 | N43: [[802 156] [708 334]] | O43: 0.57884909 | Q43: 0 | R43: 0.48 | S43: 0.5 | T43: 0.49 | U43: 812 | V43: [[406 406] [441 747]] | W43: 0.56439394
A44: 1 | B44: 0.58 | C44: 0.51 | D44: 0.54 | E44: 195 | I44: 1 | J44: 0.68 | K44: 0.32 | L44: 0.44 | M44: 1042 | Q44: 1 | R44: 0.65 | S44: 0.63 | T44: 0.64 | U44: 1188
A45: accuracy | D45: 0.54 | E45: 362 | I45: accuracy | L45: 0.57 | M45: 2000 | Q45: accuracy | T45: 0.58 | U45: 2000
...

Sheet median (1998-2023)
A1: ITA-ROE-GradientBoostingClassifier | I1: EU-ROE-GradientBoostingClassifier | Q1: USA-ROE-GradientBoostingClassifier
B2: precision | C2: recall | D2: f1-score | E2: support | F2: confusion matrix | G2: roc-auc score | J2: precision | K2: recall | L2: f1-score | M2: support | N2: confusion matrix | O2: roc-auc score | R2: precision | S2: recall | T2: f1-score | U2: support | V2: confusion matrix | W2: roc-auc score
A3: 0 | B3: 0.71 | C3: 0.65 | D3: 0.68 | E3: 196 | F3: [[127 69] [ 51 115]] | G3: 0.67036513 | I3: 0 | J3: 0.69 | K3: 0.63 | L3: 0.66 | M3: 1099 | N3: [[694 405] [311 590]] | O3: 0.64315557 | Q3: 0 | R3: 0.72 | S3: 0.54 | T3: 0.62 | U3: 991 | V3: [[537 454] [207 802]] | W3: 0.66836164
A4: 1 | B4: 0.62 | C4: 0.69 | D4: 0.66 | E4: 166 | I4: 1 | J4: 0.59 | K4: 0.65 | L4: 0.62 | M4: 901 | Q4: 1 | R4: 0.64 | S4: 0.79 | T4: 0.71 | U4: 1009
A5: accuracy | D5: 0.67 | E5: 362 | I5: accuracy | L5: 0.64 | M5: 2000 | Q5: accuracy | T5: 0.67 | U5: 2000
A6: macro avg | B6: 0.67 | C6: 0.67 | D6: 0.67 | E6: 362 | I6: macro avg | J6: 0.64 | K6: 0.64 | L6: 0.64 | M6: 2000 | Q6: macro avg | R6: 0.68 | S6: 0.67 | T6: 0.66 | U6: 2000
A7: weighted avg | B7: 0.67 | C7: 0.67 | D7: 0.67 | E7: 362 | I7: weighted avg | J7: 0.65 | K7: 0.64 | L7: 0.64 | M7: 2000 | Q7: weighted avg | R7: 0.68 | S7: 0.67 | T7: 0.66 | U7: 2000
A9: ITA-ROE-RandomForestClassifier | I9: EU-ROE-RandomForestClassifier | Q9: USA-ROE-RandomForestClassifier
B10: precision | C10: recall | D10: f1-score | E10: support | F10: confusion matrix | G10: roc-auc score | J10: precision | K10: recall | L10: f1-score | M10: support | N10: confusion matrix | O10: roc-auc score | R10: precision | S10: recall | T10: f1-score | U10: support | V10: confusion matrix | W10: roc-auc score
A11: 0 | B11: 0.65 | C11: 0.7 | D11: 0.67 | E11: 196 | F11: [[137 59] [ 75 91]] | G11: 0.62358618 | I11: 0 | J11: 0.69 | K11: 0.65 | L11: 0.67 | M11: 1099 | N11: [[711 388] [324 577]] | O11: 0.64367567 | Q11: 0 | R11: 0.69 | S11: 0.58 | T11: 0.63 | U11: 991 | V11: [[575 416] [255 754]] | W11: 0.66374826
A12: 1 | B12: 0.61 | C12: 0.55 | D12: 0.58 | E12: 166 | I12: 1 | J12: 0.6 | K12: 0.64 | L12: 0.62 | M12: 901 | Q12: 1 | R12: 0.64 | S12: 0.75 | T12: 0.69 | U12: 1009
A13: accuracy | D13: 0.63 | E13: 362 | I13: accuracy | L13: 0.64 | M13: 2000 | Q13: accuracy | T13: 0.66 | U13: 2000
A14: macro avg | B14: 0.63 | C14: 0.62 | D14: 0.62 | E14: 362 | I14: macro avg | J14: 0.64 | K14: 0.64 | L14: 0.64 | M14: 2000 | Q14: macro avg | R14: 0.67 | S14: 0.66 | T14: 0.66 | U14: 2000
A15: weighted avg | B15: 0.63 | C15: 0.63 | D15: 0.63 | E15: 362 | I15: weighted avg | J15: 0.65 | K15: 0.64 | L15: 0.64 | M15: 2000 | Q15: weighted avg | R15: 0.67 | S15: 0.66 | T15: 0.66 | U15: 2000
A17: ITA-ROE-MPLClassifier | I17: EU-ROE-MPLClassifier | Q17: USA-ROE-MPLClassifier
B18: precision | C18: recall | D18: f1-score | E18: support | F18: confusion matrix | G18: roc-auc score | J18: precision | K18: recall | L18: f1-score | M18: support | N18: confusion matrix | O18: roc-auc score | R18: precision | S18: recall | T18: f1-score | U18: support | V18: confusion matrix | W18: roc-auc score
A19: 0 | B19: 0.6 | C19: 0.61 | D19: 0.61 | E19: 196 | F19: [[120 76] [ 79 87]] | G19: 0.56817064 | I19: 0 | J19: 0.61 | K19: 0.82 | L19: 0.7 | M19: 1099 | N19: [[904 195] [576 325]] | O19: 0.59163815 | Q19: 0 | R19: 0.55 | S19: 0.93 | T19: 0.69 | U19: 991 | V19: [[922 69] [741 268]] | W19: 0.59799144
A20: 1 | B20: 0.53 | C20: 0.52 | D20: 0.53 | E20: 166 | I20: 1 | J20: 0.62 | K20: 0.36 | L20: 0.46 | M20: 901 | Q20: 1 | R20: 0.8 | S20: 0.27 | T20: 0.4 | U20: 1009
A21: accuracy | D21: 0.57 | E21: 362 | I21: accuracy | L21: 0.61 | M21: 2000 | Q21: accuracy | T21: 0.59 | U21: 2000
A22: macro avg | B22: 0.57 | C22: 0.57 | D22: 0.57 | E22: 362 | I22: macro avg | J22: 0.62 | K22: 0.59 | L22: 0.58 | M22: 2000 | Q22: macro avg | R22: 0.67 | S22: 0.6 | T22: 0.55 | U22: 2000
A23: weighted avg | B23: 0.57 | C23: 0.57 | D23: 0.57 | E23: 362 | I23: weighted avg | J23: 0.62 | K23: 0.61 | L23: 0.59 | M23: 2000 | Q23: weighted avg | R23: 0.68 | S23: 0.59 | T23: 0.55 | U23: 2000
A25: ITA-ROCE-GradientBoostingClassifier | I25: EU-ROCE-GradientBoostingClassifier | Q25: USA-ROCE-GradientBoostingClassifier
B26: precision | C26: recall | D26: f1-score | E26: support | F26: confusion matrix | G26: roc-auc score | J26: precision | K26: recall | L26: f1-score | M26: support | N26: confusion matrix | O26: roc-auc score | R26: precision | S26: recall | T26: f1-score | U26: support | V26: confusion matrix | W26: roc-auc score
A27: 0 | B27: 0.63 | C27: 0.64 | D27: 0.64 | E27: 167 | F27: [[107 60] [ 62 133]] | G27: 0.66138492 | I27: 0 | J27: 0.63 | K27: 0.55 | L27: 0.59 | M27: 958 | N27: [[524 434] [305 737]] | O27: 0.62713326 | Q27: 0 | R27: 0.7 | S27: 0.5 | T27: 0.58 | U27: 812 | V27: [[ 404 408] [ 173 1015]] | W27: 0.67595703
A28: 1 | B28: 0.69 | C28: 0.68 | D28: 0.69 | E28: 195 | I28: 1 | J28: 0.63 | K28: 0.71 | L28: 0.67 | M28: 1042 | Q28: 1 | R28: 0.71 | S28: 0.85 | T28: 0.78 | U28: 1188
A29: accuracy | D29: 0.66 | E29: 362 | I29: accuracy | L29: 0.63 | M29: 2000 | Q29: accuracy | T29: 0.71 | U29: 2000
A30: macro avg | B30: 0.66 | C30: 0.66 | D30: 0.66 | E30: 362 | I30: macro avg | J30: 0.63 | K30: 0.63 | L30: 0.63 | M30: 2000 | Q30: macro avg | R30: 0.71 | S30: 0.68 | T30: 0.68 | U30: 2000
A31: weighted avg | B31: 0.66 | C31: 0.66 | D31: 0.66 | E31: 362 | I31: weighted avg | J31: 0.63 | K31: 0.63 | L31: 0.63 | M31: 2000 | Q31: weighted avg | R31: 0.71 | S31: 0.71 | T31: 0.7 | U31: 2000
A33: ITA-ROCE-RandomForestClassifier | I33: EU-ROCE-RandomForestClassifier | Q33: USA-ROCE-RandomForestClassifier
B34: precision | C34: recall | D34: f1-score | E34: support | F34: confusion matrix | G34: roc-auc score | J34: precision | K34: recall | L34: f1-score | M34: support | N34: confusion matrix | O34: roc-auc score | R34: precision | S34: recall | T34: f1-score | U34: support | V34: confusion matrix | W34: roc-auc score
A35: 0 | B35: 0.56 | C35: 0.71 | D35: 0.62 | E35: 167 | F35: [[119 48] [ 95 100]] | G35: 0.61269768 | I35: 0 | J35: 0.61 | K35: 0.62 | L35: 0.62 | M35: 958 | N35: [[594 364] [377 665]] | O35: 0.62911877 | Q35: 0 | R35: 0.63 | S35: 0.58 | T35: 0.6 | U35: 812 | V35: [[470 342] [279 909]] | W35: 0.67198462
A36: 1 | B36: 0.68 | C36: 0.51 | D36: 0.58 | E36: 195 | I36: 1 | J36: 0.65 | K36: 0.64 | L36: 0.64 | M36: 1042 | Q36: 1 | R36: 0.73 | S36: 0.77 | T36: 0.75 | U36: 1188
A37: accuracy | D37: 0.6 | E37: 362 | I37: accuracy | L37: 0.63 | M37: 2000 | Q37: accuracy | T37: 0.69 | U37: 2000
A38: macro avg | B38: 0.62 | C38: 0.61 | D38: 0.6 | E38: 362 | I38: macro avg | J38: 0.63 | K38: 0.63 | L38: 0.63 | M38: 2000 | Q38: macro avg | R38: 0.68 | S38: 0.67 | T38: 0.67 | U38: 2000
A39: weighted avg | B39: 0.62 | C39: 0.6 | D39: 0.6 | E39: 362 | I39: weighted avg | J39: 0.63 | K39: 0.63 | L39: 0.63 | M39: 2000 | Q39: weighted avg | R39: 0.69 | S39: 0.69 | T39: 0.69 | U39: 2000
A41: ITA-ROCE-MPLClassifier | I41: EU-ROCE-MPLClassifier | Q41: USA-ROCE-MPLClassifier
B42: precision | C42: recall | D42: f1-score | E42: support | F42: confusion matrix | G42: roc-auc score | J42: precision | K42: recall | L42: f1-score | M42: support | N42: confusion matrix | O42: roc-auc score | R42: precision | S42: recall | T42: f1-score | U42: support | V42: confusion matrix | W42: roc-auc score
A43: 0 | B43: 0.5 | C43: 0.8 | D43: 0.62 | E43: 167 | F43: [[134 33] [133 62]] | G43: 0.56017196 | I43: 0 | J43: 0.61 | K43: 0.36 | L43: 0.45 | M43: 958 | N43: [[347 611] [225 817]] | O43: 0.57314102 | Q43: 0 | R43: 0.65 | S43: 0.35 | T43: 0.45 | U43: 812 | V43: [[ 281 531] [ 153 1035]] | W43: 0.60863562
A44: 1 | B44: 0.65 | C44: 0.32 | D44: 0.43 | E44: 195 | I44: 1 | J44: 0.57 | K44: 0.78 | L44: 0.66 | M44: 1042 | Q44: 1 | R44: 0.66 | S44: 0.87 | T44: 0.75 | U44: 1188
A45: accuracy | D45: 0.54 | E45: 362 | I45: accuracy | L45: 0.58 | M45: 2000 | Q45: accuracy | T45: 0.66 | U45: 2000
...

Sheet results (1998-2023)
A1: ROC-AUC | B1: ROE | D1: ROCE | F1: Utile Netto
A2: ITA | B2: =MAX('zero (1998-2023)'!G3,'zero (1998-2023)'!G11,'zero (1998-2023)'!G19,'mean (1998-2023)'!G3,'mean (1998-2023)'!G11,'mean (1998-2023)'!G19,'median (1998-2023)'!G3,'median (1998-2023)'!G11,'median (1998-2023)'!G19) -> 0.67316204 | C2: GradientBoostingClassifier - ZERO | D2: =MAX('zero (1998-2023)'!G27,'zero (1998-2023)'!G35,'zero (1998-2023)'!G43,'mean (1998-2023)'!G27,'mean (1998-2023)'!G35,'mean (1998-2023)'!G43,'median (1998-2023)'!G27,'median (1998-2023)'!G35,'median (1998-2023)'!G43) -> 0.66652848 | E2: GradientBoostingClassifier - ZERO | F2: =MAX('zero (1998-2023)'!G51,'zero (1998-2023)'!G59,'zero (1998-2023)'!G67,'mean (1998-2023)'!G51,'mean (1998-2023)'!G59,'mean (1998-2023)'!G66,'median (1998-2023)'!G51,'median (1998-2023)'!G59,'median (1998-2023)'!G67) -> 0.58980731 | G2: RandomForestClassifier - MEDIAN
A3: EU | B3: =MAX('zero (1998-2023)'!O3,'zero (1998-2023)'!O11,'zero (1998-2023)'!O19,'mean (1998-2023)'!O3,'mean (1998-2023)'!O11,'mean (1998-2023)'!O19,'median (1998-2023)'!O3,'median (1998-2023)'!O11,'median (1998-2023)'!O19) -> 0.6484747 | C3: GradientBoostingClassifier - ZERO | D3: =MAX('zero (1998-2023)'!O27,'zero (1998-2023)'!O35,'zero (1998-2023)'!O43,'mean (1998-2023)'!O27,'mean (1998-2023)'!O35,'mean (1998-2023)'!O43,'median (1998-2023)'!O27,'median (1998-2023)'!O35,'median (1998-2023)'!O43) -> 0.63624033 | E3: RandomForestClassifier - MEAN | F3: =MAX('zero (1998-2023)'!O51,'zero (1998-2023)'!O59,'zero (1998-2023)'!O67,'mean (1998-2023)'!O51,'mean (1998-2023)'!O59,'mean (1998-2023)'!O66,'median (1998-2023)'!O51,'median (1998-2023)'!O59,'median (1998-2023)'!O67) -> 0.59912735 | G3: RandomForestClassifier - MEDIAN
A4: USA | B4: =MAX('zero (1998-2023)'!W3,'zero (1998-2023)'!W11,'zero (1998-2023)'!W19,'mean (1998-2023)'!W3,'mean (1998-2023)'!W11,'mean (1998-2023)'!W19,'median (1998-2023)'!W3,'median (1998-2023)'!W11,'median (1998-2023)'!W19) -> 0.68041661 | C4: GradientBoostingClassifier - ZERO | D4: =MAX('zero (1998-2023)'!W27,'zero (1998-2023)'!W35,'zero (1998-2023)'!W43,'mean (1998-2023)'!W27,'mean (1998-2023)'!W35,'mean (1998-2023)'!W43,'median (1998-2023)'!W27,'median (1998-2023)'!W35,'median (1998-2023)'!W43) -> 0.68367584 | E4: RandomForestClassifier - ZERO | F4: =MAX('zero (1998-2023)'!W51,'zero (1998-2023)'!W59,'zero (1998-2023)'!W67,'mean (1998-2023)'!W51,'mean (1998-2023)'!W59,'mean (1998-2023)'!W66,'median (1998-2023)'!W51,'median (1998-2023)'!W59,'median (1998-2023)'!W67) -> 0.62282726 | G4: MPLClassifier - MEDIAN
A6: ACCURACY | B6: ROE | D6: ROCE | F6: Utile Netto
A7: ITA | B7: =MAX('zero (1998-2023)'!D5,'zero (1998-2023)'!D13,'zero (1998-2023)'!D21,'mean (1998-2023)'!D5,'mean (1998-2023)'!D13,'mean (1998-2023)'!D21,'median (1998-2023)'!D5,'median (1998-2023)'!D13,'median (1998-2023)'!D21) -> 0.67 | C7: GradientBoostingClassifier - ZERO; GradientBoostingClassifier - MEAN; GradientBoostingClassifier - MEDIAN; | D7: =MAX('zero (1998-2023)'!D29,'zero (1998-2023)'!D37,'zero (1998-2023)'!D45,'mean (1998-2023)'!D29,'mean (1998-2023)'!D37,'mean (1998-2023)'!D45,'median (1998-2023)'!D29,'median (1998-2023)'!D37,'median (1998-2023)'!D45) -> 0.67 | E7: GradientBoostingClassifier - ZERO | F7: =MAX('zero (1998-2023)'!D53,'zero (1998-2023)'!D61,'zero (1998-2023)'!D69,'mean (1998-2023)'!D53,'mean (1998-2023)'!D61,'mean (1998-2023)'!D69,'median (1998-2023)'!D53,'median (1998-2023)'!D61,'median (1998-2023)'!D69) -> 0.61 | G7: GradientBoostingClassifier - MEAN
A8: EU | B8: =MAX('zero (1998-2023)'!L5,'zero (1998-2023)'!L13,'zero (1998-2023)'!L21,'mean (1998-2023)'!L5,'mean (1998-2023)'!L13,'mean (1998-2023)'!L21,'median (1998-2023)'!L5,'median (1998-2023)'!L13,'median (1998-2023)'!L21) -> 0.64 | C8: GradientBoostingClassifier - ZERO; RandomForestClassifier - ZERO; GradientBoostingClassifier - MEAN; RandomForestClassifier - MEAN; GradientBoostingClassifier - MEDIAN; RandomForestClassifier - MEDIAN; | D8: =MAX('zero (1998-2023)'!L29,'zero (1998-2023)'!L37,'zero (1998-2023)'!L45,'mean (1998-2023)'!L29,'mean (1998-2023)'!L37,'mean (1998-2023)'!L45,'median (1998-2023)'!L29,'median (1998-2023)'!L37,'median (1998-2023)'!L45) -> 0.64 | E8: RandomForestClassifier - MEAN | F8: =MAX('zero (1998-2023)'!L53,'zero (1998-2023)'!L61,'zero (1998-2023)'!L69,'mean (1998-2023)'!L53,'mean (1998-2023)'!L61,'mean (1998-2023)'!L69,'median (1998-2023)'!L53,'median (1998-2023)'!L61,'median (1998-2023)'!L69) -> 0.61 | G8: GradientBoostingClassifier - ZERO
A9: USA | B9: =MAX('zero (1998-2023)'!T5,'zero (1998-2023)'!T13,'zero (1998-2023)'!T21,'mean (1998-2023)'!T5,'mean (1998-2023)'!T13,'mean (1998-2023)'!T21,'median (1998-2023)'!T5,'median (1998-2023)'!T13,'median (1998-2023)'!T21) -> 0.68 | C9: GradientBoostingClassifier - ZERO; GradientBoostingClassifier - MEAN; | D9: =MAX('zero (1998-2023)'!T29,'zero (1998-2023)'!T37,'zero (1998-2023)'!T45,'mean (1998-2023)'!T29,'mean (1998-2023)'!T37,'mean (1998-2023)'!T45,'median (1998-2023)'!T29,'median (1998-2023)'!T37,'median (1998-2023)'!T45) -> 0.71 | E9: GradientBoostingClassifier - ZERO; GradientBoostingClassifier - MEAN; GradientBoostingClassifier - MEDIAN; | F9: =MAX('zero (1998-2023)'!T53,'zero (1998-2023)'!T61,'zero (1998-2023)'!T69,'mean (1998-2023)'!T53,'mean (1998-2023)'!T61,'mean (1998-2023)'!T69,'median (1998-2023)'!T53,'median (1998-2023)'!T61,'median (1998-2023)'!T69) -> 0.63 | G9: GradientBoostingClassifier - ZERO; GradientBoostingClassifier - MEAN; GradientBoostingClassifier - MEDIAN; RandomForestClassifer - MEDIAN;
