Workbook

Sheet zero (1995-2023)
A1: ITA-ROE-GradientBoostingClassifier | I1: EU-ROE-GradientBoostingClassifier | Q1: USA-ROE-GradientBoostingClassifier
B2: precision | C2: recall | D2: f1-score | E2: support | F2: confusion matrix | G2: roc-auc score | J2: precision | K2: recall | L2: f1-score | M2: support | N2: confusion matrix | O2: roc-auc score | R2: precision | S2: recall | T2: f1-score | U2: support | V2: confusion matrix | W2: roc-auc score
A3: 0 | B3: 0.76 | C3: 0.63 | D3: 0.69 | E3: 192 | F3: [[121 71] | G3: 0.68154252 | I3: 0 | J3: 0.68 | K3: 0.63 | L3: 0.65 | M3: 1076 | N3: [[674 402] | O3: 0.63122028 | Q3: 0 | R3: 0.73 | S3: 0.54 | T3: 0.62 | U3: 987 | V3: [[529 458] | W3: 0.66704726
A4: 1 | B4: 0.6 | C4: 0.73 | D4: 0.66 | E4: 146 | F4: [ 39 107]] | I4: 1 | J4: 0.58 | K4: 0.64 | L4: 0.6 | M4: 860 | N4: [313 547]] | Q4: 1 | R4: 0.63 | S4: 0.8 | T4: 0.7 | U4: 961 | V4: [194 767]]
A5: accuracy | D5: 0.67 | E5: 338 | I5: accuracy | L5: 0.63 | M5: 1936 | Q5: accuracy | T5: 0.67 | U5: 1948
A6: macro avg | B6: 0.68 | C6: 0.68 | D6: 0.67 | E6: 338 | I6: macro avg | J6: 0.63 | K6: 0.63 | L6: 0.63 | M6: 1936 | Q6: macro avg | R6: 0.68 | S6: 0.67 | T6: 0.66 | U6: 1948
A7: weighted avg | B7: 0.69 | C7: 0.67 | D7: 0.68 | E7: 338 | I7: weighted avg | J7: 0.64 | K7: 0.63 | L7: 0.63 | M7: 1936 | Q7: weighted avg | R7: 0.68 | S7: 0.67 | T7: 0.66 | U7: 1948
A9: ITA-ROE-RandomForestClassifier | I9: EU-ROE-RandomForestClassifier | Q9: USA-ROE-RandomForestClassifier
B10: precision | C10: recall | D10: f1-score | E10: support | F10: confusion matrix | G10: roc-auc score | J10: precision | K10: recall | L10: f1-score | M10: support | N10: confusion matrix | O10: roc-auc score | R10: precision | S10: recall | T10: f1-score | U10: support | V10: confusion matrix | W10: roc-auc score
A11: 0 | B11: 0.66 | C11: 0.76 | D11: 0.71 | E11: 192 | F11: [[145 47] | G11: 0.62417951 | I11: 0 | J11: 0.68 | K11: 0.64 | L11: 0.66 | M11: 1076 | N11: [[690 386] | O11: 0.63167848 | Q11: 0 | R11: 0.68 | S11: 0.57 | T11: 0.62 | U11: 987 | V11: [[565 422] | W11: 0.64990453
A12: 1 | B12: 0.61 | C12: 0.49 | D12: 0.54 | E12: 146 | F12: [ 74 72]] | I12: 1 | J12: 0.58 | K12: 0.62 | L12: 0.6 | M12: 860 | N12: [325 535]] | Q12: 1 | R12: 0.62 | S12: 0.73 | T12: 0.67 | U12: 961 | V12: [262 699]]
A13: accuracy | D13: 0.64 | E13: 338 | I13: accuracy | L13: 0.63 | M13: 1936 | Q13: accuracy | T13: 0.65 | U13: 1948
A14: macro avg | B14: 0.63 | C14: 0.62 | D14: 0.62 | E14: 338 | I14: macro avg | J14: 0.63 | K14: 0.63 | L14: 0.63 | M14: 1936 | Q14: macro avg | R14: 0.65 | S14: 0.65 | T14: 0.65 | U14: 1948
A15: weighted avg | B15: 0.64 | C15: 0.64 | D15: 0.64 | E15: 338 | I15: weighted avg | J15: 0.64 | K15: 0.63 | L15: 0.63 | M15: 1936 | Q15: weighted avg | R15: 0.65 | S15: 0.65 | T15: 0.65 | U15: 1948
A17: ITA-ROE-MPLClassifier | I17: EU-ROE-MPLClassifier | Q17: USA-ROE-MPLClassifier
B18: precision | C18: recall | D18: f1-score | E18: support | F18: confusion matrix | G18: roc-auc score | J18: precision | K18: recall | L18: f1-score | M18: support | N18: confusion matrix | O18: roc-auc score | R18: precision | S18: recall | T18: f1-score | U18: support | V18: confusion matrix | W18: roc-auc score
A19: 0 | B19: 0.61 | C19: 0.59 | D19: 0.6 | E19: 192 | F19: [[114 78] | G19: 0.546875 | I19: 0 | J19: 0.65 | K19: 0.64 | L19: 0.64 | M19: 1076 | N19: [[684 392] | O19: 0.60389038 | Q19: 0 | R19: 0.65 | S19: 0.5 | T19: 0.57 | U19: 987 | V19: [[493 494] | W19: 0.61291008
A20: 1 | B20: 0.48 | C20: 0.5 | D20: 0.49 | E20: 146 | F20: [ 73 73]] | I20: 1 | J20: 0.56 | K20: 0.57 | L20: 0.56 | M20: 860 | N20: [368 492]] | Q20: 1 | R20: 0.59 | S20: 0.73 | T20: 0.65 | U20: 961 | V20: [263 698]]
A21: accuracy | D21: 0.55 | E21: 338 | I21: accuracy | L21: 0.61 | M21: 1936 | Q21: accuracy | T21: 0.61 | U21: 1948
A22: macro avg | B22: 0.55 | C22: 0.55 | D22: 0.55 | E22: 338 | I22: macro avg | J22: 0.6 | K22: 0.6 | L22: 0.6 | M22: 1936 | Q22: macro avg | R22: 0.62 | S22: 0.61 | T22: 0.61 | U22: 1948
A23: weighted avg | B23: 0.56 | C23: 0.55 | D23: 0.55 | E23: 338 | I23: weighted avg | J23: 0.61 | K23: 0.61 | L23: 0.61 | M23: 1936 | Q23: weighted avg | R23: 0.62 | S23: 0.61 | T23: 0.61 | U23: 1948
A25: ITA-ROCE-GradientBoostingClassifier | I25: EU-ROCE-GradientBoostingClassifier | Q25: USA-ROCE-GradientBoostingClassifier
B26: precision | C26: recall | D26: f1-score | E26: support | F26: confusion matrix | G26: roc-auc score | J26: precision | K26: recall | L26: f1-score | M26: support | N26: confusion matrix | O26: roc-auc score | R26: precision | S26: recall | T26: f1-score | U26: support | V26: confusion matrix | W26: roc-auc score
A27: 0 | B27: 0.6 | C27: 0.69 | D27: 0.64 | E27: 162 | F27: [[111 51] | G27: 0.63236532 | I27: 0 | J27: 0.62 | K27: 0.58 | L27: 0.6 | M27: 934 | N27: [[541 393] | O27: 0.6239459 | Q27: 0 | R27: 0.69 | S27: 0.5 | T27: 0.58 | U27: 808 | V27: [[402 406] | W27: 0.6702536
A28: 1 | B28: 0.67 | C28: 0.58 | D28: 0.62 | E28: 176 | F28: [ 74 102]] | I28: 1 | J28: 0.63 | K28: 0.67 | L28: 0.65 | M28: 1002 | N28: [332 670]] | Q28: 1 | R28: 0.7 | S28: 0.84 | T28: 0.77 | U28: 1140 | V28: [179 961]]
A29: accuracy | D29: 0.63 | E29: 338 | I29: accuracy | L29: 0.63 | M29: 1936 | Q29: accuracy | T29: 0.7 | U29: 1948
A30: macro avg | B30: 0.63 | C30: 0.63 | D30: 0.63 | E30: 338 | I30: macro avg | J30: 0.62 | K30: 0.62 | L30: 0.62 | M30: 1936 | Q30: macro avg | R30: 0.7 | S30: 0.67 | T30: 0.67 | U30: 1948
A31: weighted avg | B31: 0.63 | C31: 0.63 | D31: 0.63 | E31: 338 | I31: weighted avg | J31: 0.63 | K31: 0.63 | L31: 0.62 | M31: 1936 | Q31: weighted avg | R31: 0.7 | S31: 0.7 | T31: 0.69 | U31: 1948
A33: ITA-ROCE-RandomForestClassifier | I33: EU-ROCE-RandomForestClassifier | Q33: USA-ROCE-RandomForestClassifier
B34: precision | C34: recall | D34: f1-score | E34: support | F34: confusion matrix | G34: roc-auc score | J34: precision | K34: recall | L34: f1-score | M34: support | N34: confusion matrix | O34: roc-auc score | R34: precision | S34: recall | T34: f1-score | U34: support | V34: confusion matrix | W34: roc-auc score
A35: 0 | B35: 0.55 | C35: 0.72 | D35: 0.62 | E35: 162 | F35: [[116 46] | G35: 0.59097924 | I35: 0 | J35: 0.6 | K35: 0.63 | L35: 0.62 | M35: 934 | N35: [[590 344] | O35: 0.62023704 | Q35: 0 | R35: 0.63 | S35: 0.58 | T35: 0.6 | U35: 808 | V35: [[468 340] | W35: 0.66767414
A36: 1 | B36: 0.64 | C36: 0.47 | D36: 0.54 | E36: 176 | F36: [ 94 82]] | I36: 1 | J36: 0.64 | K36: 0.61 | L36: 0.62 | M36: 1002 | N36: [392 610]] | Q36: 1 | R36: 0.72 | S36: 0.76 | T36: 0.74 | U36: 1140 | V36: [278 862]]
A37: accuracy | D37: 0.59 | E37: 338 | I37: accuracy | L37: 0.62 | M37: 1936 | Q37: accuracy | T37: 0.68 | U37: 1948
A38: macro avg | B38: 0.6 | C38: 0.59 | D38: 0.58 | E38: 338 | I38: macro avg | J38: 0.62 | K38: 0.62 | L38: 0.62 | M38: 1936 | Q38: macro avg | R38: 0.67 | S38: 0.67 | T38: 0.67 | U38: 1948
A39: weighted avg | B39: 0.6 | C39: 0.59 | D39: 0.58 | E39: 338 | I39: weighted avg | J39: 0.62 | K39: 0.62 | L39: 0.62 | M39: 1936 | Q39: weighted avg | R39: 0.68 | S39: 0.68 | T39: 0.68 | U39: 1948
A41: ITA-ROCE-MPLClassifier | I41: EU-ROCE-MPLClassifier | Q41: USA-ROCE-MPLClassifier
B42: precision | C42: recall | D42: f1-score | E42: support | F42: confusion matrix | G42: roc-auc score | J42: precision | K42: recall | L42: f1-score | M42: support | N42: confusion matrix | O42: roc-auc score | R42: precision | S42: recall | T42: f1-score | U42: support | V42: confusion matrix | W42: roc-auc score
A43: 0 | B43: 0.5 | C43: 0.67 | D43: 0.57 | E43: 162 | F43: [[108 54] | G43: 0.52935606 | I43: 0 | J43: 0.6 | K43: 0.5 | L43: 0.55 | M43: 934 | N43: [[471 463] | O43: 0.59295969 | Q43: 0 | R43: 0.66 | S43: 0.14 | T43: 0.23 | U43: 808 | V43: [[ 115 693] | W43: 0.54528617
A44: 1 | B44: 0.56 | C44: 0.39 | D44: 0.46 | E44: 176 | F44: [107 69]] | I44: 1 | J44: 0.6 | K44: 0.68 | L44: 0.64 | M44: 1002 | N44: [319 683]] | Q44: 1 | R44: 0.61 | S44: 0.95 | T44: 0.74 | U44: 1140 | V44: [ 59 1081]]
A45: accuracy | D45: 0.52 | E45: 338 | I45: accuracy | L45: 0.6 | M45: 1936 | Q45: accuracy | T45: 0.61 | U45: 1948
...

Sheet mean (1995-2023)
A1: ITA-ROE-GradientBoostingClassifier | I1: EU-ROE-GradientBoostingClassifier | Q1: USA-ROE-GradientBoostingClassifier
B2: precision | C2: recall | D2: f1-score | E2: support | F2: confusion matrix | G2: roc-auc score | J2: precision | K2: recall | L2: f1-score | M2: support | N2: confusion matrix | O2: roc-auc score | R2: precision | S2: recall | T2: f1-score | U2: support | V2: confusion matrix | W2: roc-auc score
A3: 0 | B3: 0.7 | C3: 0.65 | D3: 0.67 | E3: 192 | F3: [[125 67] | G3: 0.64058933 | I3: 0 | J3: 0.69 | K3: 0.63 | L3: 0.66 | M3: 1075 | N3: [[675 400] | O3: 0.63625314 | Q3: 0 | R3: 0.73 | S3: 0.54 | T3: 0.62 | U3: 987 | V3: [[536 451] | W3: 0.67059336
A4: 1 | B4: 0.58 | C4: 0.63 | D4: 0.6 | E4: 146 | F4: [ 54 92]] | I4: 1 | J4: 0.58 | K4: 0.64 | L4: 0.61 | M4: 861 | N4: [306 555]] | Q4: 1 | R4: 0.63 | S4: 0.8 | T4: 0.7 | U4: 961 | V4: [194 767]]
A5: accuracy | D5: 0.64 | E5: 338 | I5: accuracy | L5: 0.64 | M5: 1936 | Q5: accuracy | T5: 0.67 | U5: 1948
A6: macro avg | B6: 0.64 | C6: 0.64 | D6: 0.64 | E6: 338 | I6: macro avg | J6: 0.63 | K6: 0.64 | L6: 0.63 | M6: 1936 | Q6: macro avg | R6: 0.68 | S6: 0.67 | T6: 0.66 | U6: 1948
A7: weighted avg | B7: 0.65 | C7: 0.64 | D7: 0.64 | E7: 338 | I7: weighted avg | J7: 0.64 | K7: 0.64 | L7: 0.64 | M7: 1936 | Q7: weighted avg | R7: 0.68 | S7: 0.67 | T7: 0.66 | U7: 1948
A9: ITA-ROE-RandomForestClassifier | I9: EU-ROE-RandomForestClassifier | Q9: USA-ROE-RandomForestClassifier
B10: precision | C10: recall | D10: f1-score | E10: support | F10: confusion matrix | G10: roc-auc score | J10: precision | K10: recall | L10: f1-score | M10: support | N10: confusion matrix | O10: roc-auc score | R10: precision | S10: recall | T10: f1-score | U10: support | V10: confusion matrix | W10: roc-auc score
A11: 0 | B11: 0.64 | C11: 0.74 | D11: 0.69 | E11: 192 | F11: [[142 50] | G11: 0.59581906 | I11: 0 | J11: 0.68 | K11: 0.67 | L11: 0.68 | M11: 1075 | N11: [[724 351] | O11: 0.63929935 | Q11: 0 | R11: 0.68 | S11: 0.57 | T11: 0.62 | U11: 987 | V11: [[559 428] | W11: 0.64686502
A12: 1 | B12: 0.57 | C12: 0.45 | D12: 0.5 | E12: 146 | F12: [ 80 66]] | I12: 1 | J12: 0.6 | K12: 0.61 | L12: 0.6 | M12: 861 | N12: [340 521]] | Q12: 1 | R12: 0.62 | S12: 0.73 | T12: 0.67 | U12: 961 | V12: [262 699]]
A13: accuracy | D13: 0.62 | E13: 338 | I13: accuracy | L13: 0.64 | M13: 1936 | Q13: accuracy | T13: 0.65 | U13: 1948
A14: macro avg | B14: 0.6 | C14: 0.6 | D14: 0.59 | E14: 338 | I14: macro avg | J14: 0.64 | K14: 0.64 | L14: 0.64 | M14: 1936 | Q14: macro avg | R14: 0.65 | S14: 0.65 | T14: 0.64 | U14: 1948
A15: weighted avg | B15: 0.61 | C15: 0.62 | D15: 0.61 | E15: 338 | I15: weighted avg | J15: 0.64 | K15: 0.64 | L15: 0.64 | M15: 1936 | Q15: weighted avg | R15: 0.65 | S15: 0.65 | T15: 0.64 | U15: 1948
A17: ITA-ROE-MPLClassifier | I17: EU-ROE-MPLClassifier | Q17: USA-ROE-MPLClassifier
B18: precision | C18: recall | D18: f1-score | E18: support | F18: confusion matrix | G18: roc-auc score | J18: precision | K18: recall | L18: f1-score | M18: support | N18: confusion matrix | O18: roc-auc score | R18: precision | S18: recall | T18: f1-score | U18: support | V18: confusion matrix | W18: roc-auc score
A19: 0 | B19: 0.63 | C19: 0.47 | D19: 0.54 | E19: 192 | F19: [[ 90 102] | G19: 0.55629281 | I19: 0 | J19: 0.7 | K19: 0.37 | L19: 0.48 | M19: 1075 | N19: [[395 680] | O19: 0.58499851 | Q19: 0 | R19: 0.53 | S19: 0.96 | T19: 0.69 | U19: 987 | V19: [[951 36] | W19: 0.5494008
A20: 1 | B20: 0.48 | C20: 0.64 | D20: 0.55 | E20: 146 | F20: [ 52 94]] | I20: 1 | J20: 0.5 | K20: 0.8 | L20: 0.62 | M20: 861 | N20: [170 691]] | Q20: 1 | R20: 0.78 | S20: 0.14 | T20: 0.23 | U20: 961 | V20: [831 130]]
A21: accuracy | D21: 0.54 | E21: 338 | I21: accuracy | L21: 0.56 | M21: 1936 | Q21: accuracy | T21: 0.55 | U21: 1948
A22: macro avg | B22: 0.56 | C22: 0.56 | D22: 0.54 | E22: 338 | I22: macro avg | J22: 0.6 | K22: 0.58 | L22: 0.55 | M22: 1936 | Q22: macro avg | R22: 0.66 | S22: 0.55 | T22: 0.46 | U22: 1948
A23: weighted avg | B23: 0.57 | C23: 0.54 | D23: 0.54 | E23: 338 | I23: weighted avg | J23: 0.61 | K23: 0.56 | L23: 0.54 | M23: 1936 | Q23: weighted avg | R23: 0.66 | S23: 0.55 | T23: 0.46 | U23: 1948
A25: ITA-ROCE-GradientBoostingClassifier | I25: EU-ROCE-GradientBoostingClassifier | Q25: USA-ROCE-GradientBoostingClassifier
B26: precision | C26: recall | D26: f1-score | E26: support | F26: confusion matrix | G26: roc-auc score | J26: precision | K26: recall | L26: f1-score | M26: support | N26: confusion matrix | O26: roc-auc score | R26: precision | S26: recall | T26: f1-score | U26: support | V26: confusion matrix | W26: roc-auc score
A27: 0 | B27: 0.6 | C27: 0.68 | D27: 0.64 | E27: 163 | F27: [[111 52] | G27: 0.63191937 | I27: 0 | J27: 0.6 | K27: 0.65 | L27: 0.63 | M27: 932 | N27: [[608 324] | O27: 0.62697707 | Q27: 0 | R27: 0.68 | S27: 0.56 | T27: 0.61 | U27: 810 | V27: [[452 358] | W27: 0.68586648
A28: 1 | B28: 0.66 | C28: 0.58 | D28: 0.62 | E28: 175 | F28: [ 73 102]] | I28: 1 | J28: 0.65 | K28: 0.6 | L28: 0.63 | M28: 1004 | N28: [400 604]] | Q28: 1 | R28: 0.72 | S28: 0.81 | T28: 0.76 | U28: 1138 | V28: [212 926]]
A29: accuracy | D29: 0.63 | E29: 338 | I29: accuracy | L29: 0.63 | M29: 1936 | Q29: accuracy | T29: 0.71 | U29: 1948
A30: macro avg | B30: 0.63 | C30: 0.63 | D30: 0.63 | E30: 338 | I30: macro avg | J30: 0.63 | K30: 0.63 | L30: 0.63 | M30: 1936 | Q30: macro avg | R30: 0.7 | S30: 0.69 | T30: 0.69 | U30: 1948
A31: weighted avg | B31: 0.63 | C31: 0.63 | D31: 0.63 | E31: 338 | I31: weighted avg | J31: 0.63 | K31: 0.63 | L31: 0.63 | M31: 1936 | Q31: weighted avg | R31: 0.7 | S31: 0.71 | T31: 0.7 | U31: 1948
A33: ITA-ROCE-RandomForestClassifier | I33: EU-ROCE-RandomForestClassifier | Q33: USA-ROCE-RandomForestClassifier
B34: precision | C34: recall | D34: f1-score | E34: support | F34: confusion matrix | G34: roc-auc score | J34: precision | K34: recall | L34: f1-score | M34: support | N34: confusion matrix | O34: roc-auc score | R34: precision | S34: recall | T34: f1-score | U34: support | V34: confusion matrix | W34: roc-auc score
A35: 0 | B35: 0.56 | C35: 0.69 | D35: 0.62 | E35: 163 | F35: [[113 50] | G35: 0.59234005 | I35: 0 | J35: 0.6 | K35: 0.67 | L35: 0.63 | M35: 932 | N35: [[624 308] | O35: 0.62360857 | Q35: 0 | R35: 0.63 | S35: 0.57 | T35: 0.6 | U35: 810 | V35: [[462 348] | W35: 0.66611664
A36: 1 | B36: 0.63 | C36: 0.49 | D36: 0.55 | E36: 175 | F36: [ 89 86]] | I36: 1 | J36: 0.65 | K36: 0.58 | L36: 0.61 | M36: 1004 | N36: [424 580]] | Q36: 1 | R36: 0.71 | S36: 0.76 | T36: 0.74 | U36: 1138 | V36: [271 867]]
A37: accuracy | D37: 0.59 | E37: 338 | I37: accuracy | L37: 0.62 | M37: 1936 | Q37: accuracy | T37: 0.68 | U37: 1948
A38: macro avg | B38: 0.6 | C38: 0.59 | D38: 0.59 | E38: 338 | I38: macro avg | J38: 0.62 | K38: 0.62 | L38: 0.62 | M38: 1936 | Q38: macro avg | R38: 0.67 | S38: 0.67 | T38: 0.67 | U38: 1948
A39: weighted avg | B39: 0.6 | C39: 0.59 | D39: 0.58 | E39: 338 | I39: weighted avg | J39: 0.63 | K39: 0.62 | L39: 0.62 | M39: 1936 | Q39: weighted avg | R39: 0.68 | S39: 0.68 | T39: 0.68 | U39: 1948
A41: ITA-ROCE-MPLClassifier | I41: EU-ROCE-MPLClassifier | Q41: USA-ROCE-MPLClassifier
B42: precision | C42: recall | D42: f1-score | E42: support | F42: confusion matrix | G42: roc-auc score | J42: precision | K42: recall | L42: f1-score | M42: support | N42: confusion matrix | O42: roc-auc score | R42: precision | S42: recall | T42: f1-score | U42: support | V42: confusion matrix | W42: roc-auc score
A43: 0 | B43: 0.52 | C43: 0.67 | D43: 0.58 | E43: 163 | F43: [[109 54] | G43: 0.5457844 | I43: 0 | J43: 0.57 | K43: 0.53 | L43: 0.55 | M43: 932 | N43: [[491 441] | O43: 0.57566301 | Q43: 0 | R43: 0.65 | S43: 0.12 | T43: 0.21 | U43: 810 | V43: [[ 99 711] | W43: 0.53782464
A44: 1 | B44: 0.58 | C44: 0.42 | D44: 0.49 | E44: 175 | F44: [101 74]] | I44: 1 | J44: 0.59 | K44: 0.62 | L44: 0.61 | M44: 1004 | N44: [377 627]] | Q44: 1 | R44: 0.6 | S44: 0.95 | T44: 0.74 | U44: 1138 | V44: [ 53 1085]]
A45: accuracy | D45: 0.54 | E45: 338 | I45: accuracy | L45: 0.58 | M45: 1936 | Q45: accuracy | T45: 0.61 | U45: 1948
...

Sheet median (1995-2023)
A1: ITA-ROE-GradientBoostingClassifier | I1: EU-ROE-GradientBoostingClassifier | Q1: USA-ROE-GradientBoostingClassifier
B2: precision | C2: recall | D2: f1-score | E2: support | F2: confusion matrix | G2: roc-auc score | J2: precision | K2: recall | L2: f1-score | M2: support | N2: confusion matrix | O2: roc-auc score | R2: precision | S2: recall | T2: f1-score | U2: support | V2: confusion matrix | W2: roc-auc score
A3: 0 | B3: 0.68 | C3: 0.67 | D3: 0.67 | E3: 192 | F3: [[128 64] | G3: 0.62785388 | I3: 0 | J3: 0.68 | K3: 0.63 | L3: 0.65 | M3: 1076 | N3: [[674 402] | O3: 0.63122028 | Q3: 0 | R3: 0.73 | S3: 0.54 | T3: 0.62 | U3: 987 | V3: [[529 458] | W3: 0.66704726
A4: 1 | B4: 0.57 | C4: 0.59 | D4: 0.58 | E4: 146 | F4: [ 60 86]] | I4: 1 | J4: 0.58 | K4: 0.64 | L4: 0.6 | M4: 860 | N4: [313 547]] | Q4: 1 | R4: 0.63 | S4: 0.8 | T4: 0.7 | U4: 961 | V4: [194 767]]
A5: accuracy | D5: 0.63 | E5: 338 | I5: accuracy | L5: 0.63 | M5: 1936 | Q5: accuracy | T5: 0.67 | U5: 1948
A6: macro avg | B6: 0.63 | C6: 0.63 | D6: 0.63 | E6: 338 | I6: macro avg | J6: 0.63 | K6: 0.63 | L6: 0.63 | M6: 1936 | Q6: macro avg | R6: 0.68 | S6: 0.67 | T6: 0.66 | U6: 1948
A7: weighted avg | B7: 0.63 | C7: 0.63 | D7: 0.63 | E7: 338 | I7: weighted avg | J7: 0.64 | K7: 0.63 | L7: 0.63 | M7: 1936 | Q7: weighted avg | R7: 0.68 | S7: 0.67 | T7: 0.66 | U7: 1948
A9: ITA-ROE-RandomForestClassifier | I9: EU-ROE-RandomForestClassifier | Q9: USA-ROE-RandomForestClassifier
B10: precision | C10: recall | D10: f1-score | E10: support | F10: confusion matrix | G10: roc-auc score | J10: precision | K10: recall | L10: f1-score | M10: support | N10: confusion matrix | O10: roc-auc score | R10: precision | S10: recall | T10: f1-score | U10: support | V10: confusion matrix | W10: roc-auc score
A11: 0 | B11: 0.65 | C11: 0.76 | D11: 0.7 | E11: 192 | F11: [[146 46] | G11: 0.6165097 | I11: 0 | J11: 0.68 | K11: 0.64 | L11: 0.66 | M11: 1076 | N11: [[690 386] | O11: 0.63167848 | Q11: 0 | R11: 0.68 | S11: 0.57 | T11: 0.62 | U11: 987 | V11: [[565 422] | W11: 0.64990453
A12: 1 | B12: 0.6 | C12: 0.47 | D12: 0.53 | E12: 146 | F12: [ 77 69]] | I12: 1 | J12: 0.58 | K12: 0.62 | L12: 0.6 | M12: 860 | N12: [325 535]] | Q12: 1 | R12: 0.62 | S12: 0.73 | T12: 0.67 | U12: 961 | V12: [262 699]]
A13: accuracy | D13: 0.64 | E13: 338 | I13: accuracy | L13: 0.63 | M13: 1936 | Q13: accuracy | T13: 0.65 | U13: 1948
A14: macro avg | B14: 0.63 | C14: 0.62 | D14: 0.62 | E14: 338 | I14: macro avg | J14: 0.63 | K14: 0.63 | L14: 0.63 | M14: 1936 | Q14: macro avg | R14: 0.65 | S14: 0.65 | T14: 0.65 | U14: 1948
A15: weighted avg | B15: 0.63 | C15: 0.64 | D15: 0.63 | E15: 338 | I15: weighted avg | J15: 0.64 | K15: 0.63 | L15: 0.63 | M15: 1936 | Q15: weighted avg | R15: 0.65 | S15: 0.65 | T15: 0.65 | U15: 1948
A17: ITA-ROE-MPLClassifier | I17: EU-ROE-MPLClassifier | Q17: USA-ROE-MPLClassifier
B18: precision | C18: recall | D18: f1-score | E18: support | F18: confusion matrix | G18: roc-auc score | J18: precision | K18: recall | L18: f1-score | M18: support | N18: confusion matrix | O18: roc-auc score | R18: precision | S18: recall | T18: f1-score | U18: support | V18: confusion matrix | W18: roc-auc score
A19: 0 | B19: 0.57 | C19: 0.93 | D19: 0.71 | E19: 192 | F19: [[179 13] | G19: 0.50724172 | I19: 0 | J19: 0.65 | K19: 0.64 | L19: 0.64 | M19: 1076 | N19: [[684 392] | O19: 0.60389038 | Q19: 0 | R19: 0.65 | S19: 0.5 | T19: 0.57 | U19: 987 | V19: [[493 494] | W19: 0.61291008
A20: 1 | B20: 0.48 | C20: 0.08 | D20: 0.14 | E20: 146 | F20: [134 12]] | I20: 1 | J20: 0.56 | K20: 0.57 | L20: 0.56 | M20: 860 | N20: [368 492]] | Q20: 1 | R20: 0.59 | S20: 0.73 | T20: 0.65 | U20: 961 | V20: [263 698]]
A21: accuracy | D21: 0.57 | E21: 338 | I21: accuracy | L21: 0.61 | M21: 1936 | Q21: accuracy | T21: 0.61 | U21: 1948
A22: macro avg | B22: 0.53 | C22: 0.51 | D22: 0.42 | E22: 338 | I22: macro avg | J22: 0.6 | K22: 0.6 | L22: 0.6 | M22: 1936 | Q22: macro avg | R22: 0.62 | S22: 0.61 | T22: 0.61 | U22: 1948
A23: weighted avg | B23: 0.53 | C23: 0.57 | D23: 0.46 | E23: 338 | I23: weighted avg | J23: 0.61 | K23: 0.61 | L23: 0.61 | M23: 1936 | Q23: weighted avg | R23: 0.62 | S23: 0.61 | T23: 0.61 | U23: 1948
A25: ITA-ROCE-GradientBoostingClassifier | I25: EU-ROCE-GradientBoostingClassifier | Q25: USA-ROCE-GradientBoostingClassifier
B26: precision | C26: recall | D26: f1-score | E26: support | F26: confusion matrix | G26: roc-auc score | J26: precision | K26: recall | L26: f1-score | M26: support | N26: confusion matrix | O26: roc-auc score | R26: precision | S26: recall | T26: f1-score | U26: support | V26: confusion matrix | W26: roc-auc score
A27: 0 | B27: 0.59 | C27: 0.71 | D27: 0.64 | E27: 163 | F27: [[116 47] | G27: 0.62439965 | I27: 0 | J27: 0.62 | K27: 0.58 | L27: 0.6 | M27: 934 | N27: [[541 393] | O27: 0.6239459 | Q27: 0 | R27: 0.69 | S27: 0.5 | T27: 0.58 | U27: 808 | V27: [[402 406] | W27: 0.6702536
A28: 1 | B28: 0.67 | C28: 0.54 | D28: 0.59 | E28: 175 | F28: [ 81 94]] | I28: 1 | J28: 0.63 | K28: 0.67 | L28: 0.65 | M28: 1002 | N28: [332 670]] | Q28: 1 | R28: 0.7 | S28: 0.84 | T28: 0.77 | U28: 1140 | V28: [179 961]]
A29: accuracy | D29: 0.62 | E29: 338 | I29: accuracy | L29: 0.63 | M29: 1936 | Q29: accuracy | T29: 0.7 | U29: 1948
A30: macro avg | B30: 0.63 | C30: 0.62 | D30: 0.62 | E30: 338 | I30: macro avg | J30: 0.62 | K30: 0.62 | L30: 0.62 | M30: 1936 | Q30: macro avg | R30: 0.7 | S30: 0.67 | T30: 0.67 | U30: 1948
A31: weighted avg | B31: 0.63 | C31: 0.62 | D31: 0.62 | E31: 338 | I31: weighted avg | J31: 0.63 | K31: 0.63 | L31: 0.62 | M31: 1936 | Q31: weighted avg | R31: 0.7 | S31: 0.7 | T31: 0.69 | U31: 1948
A33: ITA-ROCE-RandomForestClassifier | I33: EU-ROCE-RandomForestClassifier | Q33: USA-ROCE-RandomForestClassifier
B34: precision | C34: recall | D34: f1-score | E34: support | F34: confusion matrix | G34: roc-auc score | J34: precision | K34: recall | L34: f1-score | M34: support | N34: confusion matrix | O34: roc-auc score | R34: precision | S34: recall | T34: f1-score | U34: support | V34: confusion matrix | W34: roc-auc score
A35: 0 | B35: 0.57 | C35: 0.74 | D35: 0.64 | E35: 163 | F35: [[120 43] | G35: 0.60809816 | I35: 0 | J35: 0.6 | K35: 0.63 | L35: 0.62 | M35: 934 | N35: [[590 344] | O35: 0.62023704 | Q35: 0 | R35: 0.63 | S35: 0.58 | T35: 0.6 | U35: 808 | V35: [[468 340] | W35: 0.66767414
A36: 1 | B36: 0.66 | C36: 0.48 | D36: 0.56 | E36: 175 | F36: [ 91 84]] | I36: 1 | J36: 0.64 | K36: 0.61 | L36: 0.62 | M36: 1002 | N36: [392 610]] | Q36: 1 | R36: 0.72 | S36: 0.76 | T36: 0.74 | U36: 1140 | V36: [278 862]]
A37: accuracy | D37: 0.6 | E37: 338 | I37: accuracy | L37: 0.62 | M37: 1936 | Q37: accuracy | T37: 0.68 | U37: 1948
A38: macro avg | B38: 0.62 | C38: 0.61 | D38: 0.6 | E38: 338 | I38: macro avg | J38: 0.62 | K38: 0.62 | L38: 0.62 | M38: 1936 | Q38: macro avg | R38: 0.67 | S38: 0.67 | T38: 0.67 | U38: 1948
A39: weighted avg | B39: 0.62 | C39: 0.6 | D39: 0.6 | E39: 338 | I39: weighted avg | J39: 0.62 | K39: 0.62 | L39: 0.62 | M39: 1936 | Q39: weighted avg | R39: 0.68 | S39: 0.68 | T39: 0.68 | U39: 1948
A41: ITA-ROCE-MPLClassifier | I41: EU-ROCE-MPLClassifier | Q41: USA-ROCE-MPLClassifier
B42: precision | C42: recall | D42: f1-score | E42: support | F42: confusion matrix | G42: roc-auc score | J42: precision | K42: recall | L42: f1-score | M42: support | N42: confusion matrix | O42: roc-auc score | R42: precision | S42: recall | T42: f1-score | U42: support | V42: confusion matrix | W42: roc-auc score
A43: 0 | B43: 0.53 | C43: 0.61 | D43: 0.57 | E43: 163 | F43: [[100 63] | G43: 0.55246275 | I43: 0 | J43: 0.6 | K43: 0.5 | L43: 0.55 | M43: 934 | N43: [[471 463] | O43: 0.59295969 | Q43: 0 | R43: 0.66 | S43: 0.14 | T43: 0.23 | U43: 808 | V43: [[ 115 693] | W43: 0.54528617
A44: 1 | B44: 0.58 | C44: 0.49 | D44: 0.53 | E44: 175 | F44: [ 89 86]] | I44: 1 | J44: 0.6 | K44: 0.68 | L44: 0.64 | M44: 1002 | N44: [319 683]] | Q44: 1 | R44: 0.61 | S44: 0.95 | T44: 0.74 | U44: 1140 | V44: [ 59 1081]]
A45: accuracy | D45: 0.55 | E45: 338 | I45: accuracy | L45: 0.6 | M45: 1936 | Q45: accuracy | T45: 0.61 | U45: 1948
...

Sheet results (1995-2023)
A1: ROC-AUC | B1: ROE | D1: ROCE | F1: Utile Netto
A2: ITA | B2: =MAX('zero (1995-2023)'!G3,'zero (1995-2023)'!G11,'zero (1995-2023)'!G19,'mean (1995-2023)'!G3,'mean (1995-2023)'!G11,'mean (1995-2023)'!G19,'median (1995-2023)'!G3,'median (1995-2023)'!G11,'median (1995-2023)'!G19) -> 0.68154252 | C2: GBC (zero) | D2: =MAX('zero (1995-2023)'!G27,'zero (1995-2023)'!G35,'zero (1995-2023)'!G43,'mean (1995-2023)'!G27,'mean (1995-2023)'!G35,'mean (1995-2023)'!G43,'median (1995-2023)'!G27,'median (1995-2023)'!G35,'median (1995-2023)'!G43) -> 0.63236532 | E2: GBC (zero) | F2: =MAX('zero (1995-2023)'!G51,'zero (1995-2023)'!G59,'zero (1995-2023)'!G67,'mean (1995-2023)'!G51,'mean (1995-2023)'!G59,'mean (1995-2023)'!G66,'median (1995-2023)'!G51,'median (1995-2023)'!G59,'median (1995-2023)'!G67) -> 0.58669588 | G2: GBC (mean)
A3: EU | B3: =MAX('zero (1995-2023)'!O3,'zero (1995-2023)'!O11,'zero (1995-2023)'!O19,'mean (1995-2023)'!O3,'mean (1995-2023)'!O11,'mean (1995-2023)'!O19,'median (1995-2023)'!O3,'median (1995-2023)'!O11,'median (1995-2023)'!O19) -> 0.63929935 | C3: RFC (mean) | D3: =MAX('zero (1995-2023)'!O27,'zero (1995-2023)'!O35,'zero (1995-2023)'!O43,'mean (1995-2023)'!O27,'mean (1995-2023)'!O35,'mean (1995-2023)'!O43,'median (1995-2023)'!O27,'median (1995-2023)'!O35,'median (1995-2023)'!O43) -> 0.62697707 | E3: GBC (mean) | F3: =MAX('zero (1995-2023)'!O51,'zero (1995-2023)'!O59,'zero (1995-2023)'!O67,'mean (1995-2023)'!O51,'mean (1995-2023)'!O59,'mean (1995-2023)'!O66,'median (1995-2023)'!O51,'median (1995-2023)'!O59,'median (1995-2023)'!O67) -> 0.58993326 | G3: RFC (mean)
A4: USA | B4: =MAX('zero (1995-2023)'!W3,'zero (1995-2023)'!W11,'zero (1995-2023)'!W19,'mean (1995-2023)'!W3,'mean (1995-2023)'!W11,'mean (1995-2023)'!W19,'median (1995-2023)'!W3,'median (1995-2023)'!W11,'median (1995-2023)'!W19) -> 0.67059336 | C4: GBC (mean) | D4: =MAX('zero (1995-2023)'!W27,'zero (1995-2023)'!W35,'zero (1995-2023)'!W43,'mean (1995-2023)'!W27,'mean (1995-2023)'!W35,'mean (1995-2023)'!W43,'median (1995-2023)'!W27,'median (1995-2023)'!W35,'median (1995-2023)'!W43) -> 0.68586648 | E4: GBC (mean) | F4: =MAX('zero (1995-2023)'!W51,'zero (1995-2023)'!W59,'zero (1995-2023)'!W67,'mean (1995-2023)'!W51,'mean (1995-2023)'!W59,'mean (1995-2023)'!W66,'median (1995-2023)'!W51,'median (1995-2023)'!W59,'median (1995-2023)'!W67) -> 0.60635918 | G4: GBC (mean)
A6: ACCURACY | B6: ROE | D6: ROCE | F6: Utile Netto
A7: ITA | B7: =MAX('zero (1995-2023)'!D5,'zero (1995-2023)'!D13,'zero (1995-2023)'!D21,'mean (1995-2023)'!D5,'mean (1995-2023)'!D13,'mean (1995-2023)'!D21,'median (1995-2023)'!D5,'median (1995-2023)'!D13,'median (1995-2023)'!D21) -> 0.67 | C7: GBC (zero) | D7: =MAX('zero (1995-2023)'!D29,'zero (1995-2023)'!D37,'zero (1995-2023)'!D45,'mean (1995-2023)'!D29,'mean (1995-2023)'!D37,'mean (1995-2023)'!D45,'median (1995-2023)'!D29,'median (1995-2023)'!D37,'median (1995-2023)'!D45) -> 0.63 | E7: GBC (zero, mean) | F7: =MAX('zero (1995-2023)'!D53,'zero (1995-2023)'!D61,'zero (1995-2023)'!D69,'mean (1995-2023)'!D53,'mean (1995-2023)'!D61,'mean (1995-2023)'!D69,'median (1995-2023)'!D53,'median (1995-2023)'!D61,'median (1995-2023)'!D69) -> 0.59 | G7: GBC (mean)
A8: EU | B8: =MAX('zero (1995-2023)'!L5,'zero (1995-2023)'!L13,'zero (1995-2023)'!L21,'mean (1995-2023)'!L5,'mean (1995-2023)'!L13,'mean (1995-2023)'!L21,'median (1995-2023)'!L5,'median (1995-2023)'!L13,'median (1995-2023)'!L21) -> 0.64 | C8: GBC (mean) RFC (mean) | D8: =MAX('zero (1995-2023)'!L29,'zero (1995-2023)'!L37,'zero (1995-2023)'!L45,'mean (1995-2023)'!L29,'mean (1995-2023)'!L37,'mean (1995-2023)'!L45,'median (1995-2023)'!L29,'median (1995-2023)'!L37,'median (1995-2023)'!L45) -> 0.63 | E8: GBC (zero, mean, median) | F8: =MAX('zero (1995-2023)'!L53,'zero (1995-2023)'!L61,'zero (1995-2023)'!L69,'mean (1995-2023)'!L53,'mean (1995-2023)'!L61,'mean (1995-2023)'!L69,'median (1995-2023)'!L53,'median (1995-2023)'!L61,'median (1995-2023)'!L69) -> 0.6 | G8: GBC (zero, median) RFC (zero, mean, median)
A9: USA | B9: =MAX('zero (1995-2023)'!T5,'zero (1995-2023)'!T13,'zero (1995-2023)'!T21,'mean (1995-2023)'!T5,'mean (1995-2023)'!T13,'mean (1995-2023)'!T21,'median (1995-2023)'!T5,'median (1995-2023)'!T13,'median (1995-2023)'!T21) -> 0.67 | C9: GBC (zero, mean, median) | D9: =MAX('zero (1995-2023)'!T29,'zero (1995-2023)'!T37,'zero (1995-2023)'!T45,'mean (1995-2023)'!T29,'mean (1995-2023)'!T37,'mean (1995-2023)'!T45,'median (1995-2023)'!T29,'median (1995-2023)'!T37,'median (1995-2023)'!T45) -> 0.71 | E9: GBC (mean) | F9: =MAX('zero (1995-2023)'!T53,'zero (1995-2023)'!T61,'zero (1995-2023)'!T69,'mean (1995-2023)'!T53,'mean (1995-2023)'!T61,'mean (1995-2023)'!T69,'median (1995-2023)'!T53,'median (1995-2023)'!T61,'median (1995-2023)'!T69) -> 0.63 | G9: GBC (mean)

Sheet zero (1998-2023)
A1: ITA-ROE-GradientBoostingClassifier | I1: EU-ROE-GradientBoostingClassifier | Q1: USA-ROE-GradientBoostingClassifier
B2: precision | C2: recall | D2: f1-score | E2: support | F2: confusion matrix | G2: roc-auc score | J2: precision | K2: recall | L2: f1-score | M2: support | N2: confusion matrix | O2: roc-auc score | R2: precision | S2: recall | T2: f1-score | U2: support | V2: confusion matrix | W2: roc-auc score
A3: 0 | B3: 0.71 | C3: 0.64 | D3: 0.67 | E3: 192 | F3: [[122 70] | G3: 0.6430508 | I3: 0 | J3: 0.68 | K3: 0.62 | L3: 0.65 | M3: 1076 | N3: [[671 405] | O3: 0.63098902 | Q3: 0 | R3: 0.73 | S3: 0.55 | T3: 0.63 | U3: 987 | V3: [[545 442] | W3: 0.66890914
A4: 1 | B4: 0.58 | C4: 0.65 | D4: 0.61 | E4: 146 | F4: [ 51 95]] | I4: 1 | J4: 0.58 | K4: 0.64 | L4: 0.61 | M4: 860 | N4: [311 549]] | Q4: 1 | R4: 0.63 | S4: 0.79 | T4: 0.7 | U4: 961 | V4: [206 755]]
A5: accuracy | D5: 0.64 | E5: 338 | I5: accuracy | L5: 0.63 | M5: 1936 | Q5: accuracy | T5: 0.67 | U5: 1948
A6: macro avg | B6: 0.64 | C6: 0.64 | D6: 0.64 | E6: 338 | I6: macro avg | J6: 0.63 | K6: 0.63 | L6: 0.63 | M6: 1936 | Q6: macro avg | R6: 0.68 | S6: 0.67 | T6: 0.66 | U6: 1948
A7: weighted avg | B7: 0.65 | C7: 0.64 | D7: 0.64 | E7: 338 | I7: weighted avg | J7: 0.64 | K7: 0.63 | L7: 0.63 | M7: 1936 | Q7: weighted avg | R7: 0.68 | S7: 0.67 | T7: 0.66 | U7: 1948
A9: ITA-ROE-RandomForestClassifier | I9: EU-ROE-RandomForestClassifier | Q9: USA-ROE-RandomForestClassifier
B10: precision | C10: recall | D10: f1-score | E10: support | F10: confusion matrix | G10: roc-auc score | J10: precision | K10: recall | L10: f1-score | M10: support | N10: confusion matrix | O10: roc-auc score | R10: precision | S10: recall | T10: f1-score | U10: support | V10: confusion matrix | W10: roc-auc score
A11: 0 | B11: 0.68 | C11: 0.73 | D11: 0.7 | E11: 192 | F11: [[141 51] | G11: 0.63773545 | I11: 0 | J11: 0.68 | K11: 0.65 | L11: 0.67 | M11: 1076 | N11: [[701 375] | O11: 0.63620861 | Q11: 0 | R11: 0.69 | S11: 0.58 | T11: 0.63 | U11: 987 | V11: [[569 418] | W11: 0.65817437
A12: 1 | B12: 0.61 | C12: 0.54 | D12: 0.57 | E12: 146 | F12: [ 67 79]] | I12: 1 | J12: 0.59 | K12: 0.62 | L12: 0.6 | M12: 860 | N12: [326 534]] | Q12: 1 | R12: 0.63 | S12: 0.74 | T12: 0.68 | U12: 961 | V12: [250 711]]
A13: accuracy | D13: 0.65 | E13: 338 | I13: accuracy | L13: 0.64 | M13: 1936 | Q13: accuracy | T13: 0.66 | U13: 1948
A14: macro avg | B14: 0.64 | C14: 0.64 | D14: 0.64 | E14: 338 | I14: macro avg | J14: 0.64 | K14: 0.64 | L14: 0.64 | M14: 1936 | Q14: macro avg | R14: 0.66 | S14: 0.66 | T14: 0.66 | U14: 1948
A15: weighted avg | B15: 0.65 | C15: 0.65 | D15: 0.65 | E15: 338 | I15: weighted avg | J15: 0.64 | K15: 0.64 | L15: 0.64 | M15: 1936 | Q15: weighted avg | R15: 0.66 | S15: 0.66 | T15: 0.65 | U15: 1948
A17: ITA-ROE-MPLClassifier | I17: EU-ROE-MPLClassifier | Q17: USA-ROE-MPLClassifier
B18: precision | C18: recall | D18: f1-score | E18: support | F18: confusion matrix | G18: roc-auc score | J18: precision | K18: recall | L18: f1-score | M18: support | N18: confusion matrix | O18: roc-auc score | R18: precision | S18: recall | T18: f1-score | U18: support | V18: confusion matrix | W18: roc-auc score
A19: 0 | B19: 0.6 | C19: 0.86 | D19: 0.71 | E19: 192 | F19: [[165 27] | G19: 0.54955051 | I19: 0 | J19: 0.67 | K19: 0.36 | L19: 0.47 | M19: 1076 | N19: [[389 687] | O19: 0.57145976 | Q19: 0 | R19: 0.69 | S19: 0.09 | T19: 0.16 | U19: 987 | V19: [[ 92 895] | W19: 0.52527393
A20: 1 | B20: 0.56 | C20: 0.24 | D20: 0.34 | E20: 146 | F20: [111 35]] | I20: 1 | J20: 0.49 | K20: 0.78 | L20: 0.61 | M20: 860 | N20: [188 672]] | Q20: 1 | R20: 0.51 | S20: 0.96 | T20: 0.66 | U20: 961 | V20: [ 41 920]]
A21: accuracy | D21: 0.59 | E21: 338 | I21: accuracy | L21: 0.55 | M21: 1936 | Q21: accuracy | T21: 0.52 | U21: 1948
A22: macro avg | B22: 0.58 | C22: 0.55 | D22: 0.52 | E22: 338 | I22: macro avg | J22: 0.58 | K22: 0.57 | L22: 0.54 | M22: 1936 | Q22: macro avg | R22: 0.6 | S22: 0.53 | T22: 0.41 | U22: 1948
A23: weighted avg | B23: 0.58 | C23: 0.59 | D23: 0.55 | E23: 338 | I23: weighted avg | J23: 0.59 | K23: 0.55 | L23: 0.53 | M23: 1936 | Q23: weighted avg | R23: 0.6 | S23: 0.52 | T23: 0.41 | U23: 1948
A25: ITA-ROCE-GradientBoostingClassifier | I25: EU-ROCE-GradientBoostingClassifier | Q25: USA-ROCE-GradientBoostingClassifier
B26: precision | C26: recall | D26: f1-score | E26: support | F26: confusion matrix | G26: roc-auc score | J26: precision | K26: recall | L26: f1-score | M26: support | N26: confusion matrix | O26: roc-auc score | R26: precision | S26: recall | T26: f1-score | U26: support | V26: confusion matrix | W26: roc-auc score
A27: 0 | B27: 0.61 | C27: 0.7 | D27: 0.65 | E27: 162 | F27: [[114 48] | G27: 0.64162458 | I27: 0 | J27: 0.6 | K27: 0.65 | L27: 0.63 | M27: 934 | N27: [[611 323] | O27: 0.62299598 | Q27: 0 | R27: 0.69 | S27: 0.55 | T27: 0.61 | U27: 808 | V27: [[443 365] | W27: 0.68553717
A28: 1 | B28: 0.68 | C28: 0.58 | D28: 0.63 | E28: 176 | F28: [ 74 102]] | I28: 1 | J28: 0.65 | K28: 0.59 | L28: 0.62 | M28: 1002 | N28: [409 593]] | Q28: 1 | R28: 0.72 | S28: 0.82 | T28: 0.77 | U28: 1140 | V28: [202 938]]
A29: accuracy | D29: 0.64 | E29: 338 | I29: accuracy | L29: 0.62 | M29: 1936 | Q29: accuracy | T29: 0.71 | U29: 1948
A30: macro avg | B30: 0.64 | C30: 0.64 | D30: 0.64 | E30: 338 | I30: macro avg | J30: 0.62 | K30: 0.62 | L30: 0.62 | M30: 1936 | Q30: macro avg | R30: 0.7 | S30: 0.69 | T30: 0.69 | U30: 1948
A31: weighted avg | B31: 0.64 | C31: 0.64 | D31: 0.64 | E31: 338 | I31: weighted avg | J31: 0.62 | K31: 0.62 | L31: 0.62 | M31: 1936 | Q31: weighted avg | R31: 0.71 | S31: 0.71 | T31: 0.7 | U31: 1948
A33: ITA-ROCE-RandomForestClassifier | I33: EU-ROCE-RandomForestClassifier | Q33: USA-ROCE-RandomForestClassifier
B34: precision | C34: recall | D34: f1-score | E34: support | F34: confusion matrix | G34: roc-auc score | J34: precision | K34: recall | L34: f1-score | M34: support | N34: confusion matrix | O34: roc-auc score | R34: precision | S34: recall | T34: f1-score | U34: support | V34: confusion matrix | W34: roc-auc score
A35: 0 | B35: 0.59 | C35: 0.73 | D35: 0.65 | E35: 162 | F35: [[119 43] | G35: 0.62864759 | I35: 0 | J35: 0.59 | K35: 0.67 | L35: 0.63 | M35: 934 | N35: [[624 310] | O35: 0.61997525 | Q35: 0 | R35: 0.64 | S35: 0.58 | T35: 0.61 | U35: 808 | V35: [[466 342] | W35: 0.67476985
A36: 1 | B36: 0.68 | C36: 0.52 | D36: 0.59 | E36: 176 | F36: [ 84 92]] | I36: 1 | J36: 0.65 | K36: 0.57 | L36: 0.61 | M36: 1002 | N36: [429 573]] | Q36: 1 | R36: 0.72 | S36: 0.77 | T36: 0.75 | U36: 1140 | V36: [259 881]]
A37: accuracy | D37: 0.62 | E37: 338 | I37: accuracy | L37: 0.62 | M37: 1936 | Q37: accuracy | T37: 0.69 | U37: 1948
A38: macro avg | B38: 0.63 | C38: 0.63 | D38: 0.62 | E38: 338 | I38: macro avg | J38: 0.62 | K38: 0.62 | L38: 0.62 | M38: 1936 | Q38: macro avg | R38: 0.68 | S38: 0.67 | T38: 0.68 | U38: 1948
A39: weighted avg | B39: 0.64 | C39: 0.62 | D39: 0.62 | E39: 338 | I39: weighted avg | J39: 0.62 | K39: 0.62 | L39: 0.62 | M39: 1936 | Q39: weighted avg | R39: 0.69 | S39: 0.69 | T39: 0.69 | U39: 1948
A41: ITA-ROCE-MPLClassifier | I41: EU-ROCE-MPLClassifier | Q41: USA-ROCE-MPLClassifier
B42: precision | C42: recall | D42: f1-score | E42: support | F42: confusion matrix | G42: roc-auc score | J42: precision | K42: recall | L42: f1-score | M42: support | N42: confusion matrix | O42: roc-auc score | R42: precision | S42: recall | T42: f1-score | U42: support | V42: confusion matrix | W42: roc-auc score
A43: 0 | B43: 0.51 | C43: 0.69 | D43: 0.58 | E43: 162 | F43: [[112 50] | G43: 0.53601992 | I43: 0 | J43: 0.65 | K43: 0.21 | L43: 0.32 | M43: 934 | N43: [[198 736] | O43: 0.5521035 | Q43: 0 | R43: 0.68 | S43: 0.29 | T43: 0.41 | U43: 808 | V43: [[ 237 571] | W43: 0.5984128
A44: 1 | B44: 0.57 | C44: 0.38 | D44: 0.46 | E44: 176 | F44: [109 67]] | I44: 1 | J44: 0.55 | K44: 0.89 | L44: 0.68 | M44: 1002 | N44: [108 894]] | Q44: 1 | R44: 0.64 | S44: 0.9 | T44: 0.75 | U44: 1140 | V44: [ 110 1030]]
A45: accuracy | D45: 0.53 | E45: 338 | I45: accuracy | L45: 0.56 | M45: 1936 | Q45: accuracy | T45: 0.65 | U45: 1948
...

Sheet mean (1998-2023)
A1: ITA-ROE-GradientBoostingClassifier | I1: EU-ROE-GradientBoostingClassifier | Q1: USA-ROE-GradientBoostingClassifier
B2: precision | C2: recall | D2: f1-score | E2: support | F2: confusion matrix | G2: roc-auc score | J2: precision | K2: recall | L2: f1-score | M2: support | N2: confusion matrix | O2: roc-auc score | R2: precision | S2: recall | T2: f1-score | U2: support | V2: confusion matrix | W2: roc-auc score
A3: 0 | B3: 0.69 | C3: 0.69 | D3: 0.69 | E3: 192 | F3: [[133 59] | G3: 0.64087471 | I3: 0 | J3: 0.68 | K3: 0.63 | L3: 0.66 | M3: 1075 | N3: [[680 395] | O3: 0.63335224 | Q3: 0 | R3: 0.74 | S3: 0.54 | T3: 0.63 | U3: 987 | V3: [[534 453] | W3: 0.67374252
A4: 1 | B4: 0.59 | C4: 0.59 | D4: 0.59 | E4: 146 | F4: [ 60 86]] | I4: 1 | J4: 0.58 | K4: 0.63 | L4: 0.61 | M4: 861 | N4: [315 546]] | Q4: 1 | R4: 0.63 | S4: 0.81 | T4: 0.71 | U4: 961 | V4: [186 775]]
A5: accuracy | D5: 0.65 | E5: 338 | I5: accuracy | L5: 0.63 | M5: 1936 | Q5: accuracy | T5: 0.67 | U5: 1948
A6: macro avg | B6: 0.64 | C6: 0.64 | D6: 0.64 | E6: 338 | I6: macro avg | J6: 0.63 | K6: 0.63 | L6: 0.63 | M6: 1936 | Q6: macro avg | R6: 0.69 | S6: 0.67 | T6: 0.67 | U6: 1948
A7: weighted avg | B7: 0.65 | C7: 0.65 | D7: 0.65 | E7: 338 | I7: weighted avg | J7: 0.64 | K7: 0.63 | L7: 0.63 | M7: 1936 | Q7: weighted avg | R7: 0.69 | S7: 0.67 | T7: 0.67 | U7: 1948
A9: ITA-ROE-RandomForestClassifier | I9: EU-ROE-RandomForestClassifier | Q9: USA-ROE-RandomForestClassifier
B10: precision | C10: recall | D10: f1-score | E10: support | F10: confusion matrix | G10: roc-auc score | J10: precision | K10: recall | L10: f1-score | M10: support | N10: confusion matrix | O10: roc-auc score | R10: precision | S10: recall | T10: f1-score | U10: support | V10: confusion matrix | W10: roc-auc score
A11: 0 | B11: 0.64 | C11: 0.73 | D11: 0.68 | E11: 192 | F11: [[140 52] | G11: 0.59061073 | I11: 0 | J11: 0.67 | K11: 0.67 | L11: 0.67 | M11: 1075 | N11: [[724 351] | O11: 0.63291143 | Q11: 0 | R11: 0.69 | S11: 0.57 | T11: 0.62 | U11: 987 | V11: [[560 427] | W11: 0.65413539
A12: 1 | B12: 0.56 | C12: 0.45 | D12: 0.5 | E12: 146 | F12: [ 80 66]] | I12: 1 | J12: 0.59 | K12: 0.59 | L12: 0.59 | M12: 861 | N12: [351 510]] | Q12: 1 | R12: 0.63 | S12: 0.74 | T12: 0.68 | U12: 961 | V12: [249 712]]
A13: accuracy | D13: 0.61 | E13: 338 | I13: accuracy | L13: 0.64 | M13: 1936 | Q13: accuracy | T13: 0.65 | U13: 1948
A14: macro avg | B14: 0.6 | C14: 0.59 | D14: 0.59 | E14: 338 | I14: macro avg | J14: 0.63 | K14: 0.63 | L14: 0.63 | M14: 1936 | Q14: macro avg | R14: 0.66 | S14: 0.65 | T14: 0.65 | U14: 1948
A15: weighted avg | B15: 0.6 | C15: 0.61 | D15: 0.6 | E15: 338 | I15: weighted avg | J15: 0.64 | K15: 0.64 | L15: 0.64 | M15: 1936 | Q15: weighted avg | R15: 0.66 | S15: 0.65 | T15: 0.65 | U15: 1948
A17: ITA-ROE-MPLClassifier | I17: EU-ROE-MPLClassifier | Q17: USA-ROE-MPLClassifier
B18: precision | C18: recall | D18: f1-score | E18: support | F18: confusion matrix | G18: roc-auc score | J18: precision | K18: recall | L18: f1-score | M18: support | N18: confusion matrix | O18: roc-auc score | R18: precision | S18: recall | T18: f1-score | U18: support | V18: confusion matrix | W18: roc-auc score
A19: 0 | B19: 0.61 | C19: 0.55 | D19: 0.58 | E19: 192 | F19: [[105 87] | G19: 0.54056079 | I19: 0 | J19: 0.63 | K19: 0.58 | L19: 0.6 | M19: 1075 | N19: [[624 451] | O19: 0.577689 | Q19: 0 | R19: 0.59 | S19: 0.63 | T19: 0.61 | U19: 987 | V19: [[623 364] | W19: 0.59135726
A20: 1 | B20: 0.47 | C20: 0.53 | D20: 0.5 | E20: 146 | F20: [ 68 78]] | I20: 1 | J20: 0.52 | K20: 0.57 | L20: 0.55 | M20: 861 | N20: [366 495]] | Q20: 1 | R20: 0.59 | S20: 0.55 | T20: 0.57 | U20: 961 | V20: [431 530]]
A21: accuracy | D21: 0.54 | E21: 338 | I21: accuracy | L21: 0.58 | M21: 1936 | Q21: accuracy | T21: 0.59 | U21: 1948
A22: macro avg | B22: 0.54 | C22: 0.54 | D22: 0.54 | E22: 338 | I22: macro avg | J22: 0.58 | K22: 0.58 | L22: 0.58 | M22: 1936 | Q22: macro avg | R22: 0.59 | S22: 0.59 | T22: 0.59 | U22: 1948
A23: weighted avg | B23: 0.55 | C23: 0.54 | D23: 0.54 | E23: 338 | I23: weighted avg | J23: 0.58 | K23: 0.58 | L23: 0.58 | M23: 1936 | Q23: weighted avg | R23: 0.59 | S23: 0.59 | T23: 0.59 | U23: 1948
A25: ITA-ROCE-GradientBoostingClassifier | I25: EU-ROCE-GradientBoostingClassifier | Q25: USA-ROCE-GradientBoostingClassifier
B26: precision | C26: recall | D26: f1-score | E26: support | F26: confusion matrix | G26: roc-auc score | J26: precision | K26: recall | L26: f1-score | M26: support | N26: confusion matrix | O26: roc-auc score | R26: precision | S26: recall | T26: f1-score | U26: support | V26: confusion matrix | W26: roc-auc score
A27: 0 | B27: 0.61 | C27: 0.75 | D27: 0.67 | E27: 163 | F27: [[123 40] | G27: 0.64872918 | I27: 0 | J27: 0.6 | K27: 0.66 | L27: 0.63 | M27: 932 | N27: [[611 321] | O27: 0.62858651 | Q27: 0 | R27: 0.68 | S27: 0.55 | T27: 0.6 | U27: 811 | V27: [[442 369] | W27: 0.6801548
A28: 1 | B28: 0.7 | C28: 0.54 | D28: 0.61 | E28: 175 | F28: [ 80 95]] | I28: 1 | J28: 0.65 | K28: 0.6 | L28: 0.63 | M28: 1004 | N28: [400 604]] | Q28: 1 | R28: 0.72 | S28: 0.82 | T28: 0.76 | U28: 1137 | V28: [210 927]]
A29: accuracy | D29: 0.64 | E29: 338 | I29: accuracy | L29: 0.63 | M29: 1936 | Q29: accuracy | T29: 0.7 | U29: 1948
A30: macro avg | B30: 0.65 | C30: 0.65 | D30: 0.64 | E30: 338 | I30: macro avg | J30: 0.63 | K30: 0.63 | L30: 0.63 | M30: 1936 | Q30: macro avg | R30: 0.7 | S30: 0.68 | T30: 0.68 | U30: 1948
A31: weighted avg | B31: 0.66 | C31: 0.64 | D31: 0.64 | E31: 338 | I31: weighted avg | J31: 0.63 | K31: 0.63 | L31: 0.63 | M31: 1936 | Q31: weighted avg | R31: 0.7 | S31: 0.7 | T31: 0.7 | U31: 1948
A33: ITA-ROCE-RandomForestClassifier | I33: EU-ROCE-RandomForestClassifier | Q33: USA-ROCE-RandomForestClassifier
B34: precision | C34: recall | D34: f1-score | E34: support | F34: confusion matrix | G34: roc-auc score | J34: precision | K34: recall | L34: f1-score | M34: support | N34: confusion matrix | O34: roc-auc score | R34: precision | S34: recall | T34: f1-score | U34: support | V34: confusion matrix | W34: roc-auc score
A35: 0 | B35: 0.58 | C35: 0.72 | D35: 0.64 | E35: 163 | F35: [[117 46] | G35: 0.61318142 | I35: 0 | J35: 0.6 | K35: 0.67 | L35: 0.63 | M35: 932 | N35: [[629 303] | O35: 0.62728699 | Q35: 0 | R35: 0.63 | S35: 0.56 | T35: 0.6 | U35: 811 | V35: [[456 355] | W35: 0.66547917
A36: 1 | B36: 0.66 | C36: 0.51 | D36: 0.57 | E36: 175 | F36: [ 86 89]] | I36: 1 | J36: 0.66 | K36: 0.58 | L36: 0.62 | M36: 1004 | N36: [422 582]] | Q36: 1 | R36: 0.71 | S36: 0.77 | T36: 0.74 | U36: 1137 | V36: [263 874]]
A37: accuracy | D37: 0.61 | E37: 338 | I37: accuracy | L37: 0.63 | M37: 1936 | Q37: accuracy | T37: 0.68 | U37: 1948
A38: macro avg | B38: 0.62 | C38: 0.61 | D38: 0.61 | E38: 338 | I38: macro avg | J38: 0.63 | K38: 0.63 | L38: 0.63 | M38: 1936 | Q38: macro avg | R38: 0.67 | S38: 0.67 | T38: 0.67 | U38: 1948
A39: weighted avg | B39: 0.62 | C39: 0.61 | D39: 0.61 | E39: 338 | I39: weighted avg | J39: 0.63 | K39: 0.63 | L39: 0.62 | M39: 1936 | Q39: weighted avg | R39: 0.68 | S39: 0.68 | T39: 0.68 | U39: 1948
A41: ITA-ROCE-MPLClassifier | I41: EU-ROCE-MPLClassifier | Q41: USA-ROCE-MPLClassifier
B42: precision | C42: recall | D42: f1-score | E42: support | F42: confusion matrix | G42: roc-auc score | J42: precision | K42: recall | L42: f1-score | M42: support | N42: confusion matrix | O42: roc-auc score | R42: precision | S42: recall | T42: f1-score | U42: support | V42: confusion matrix | W42: roc-auc score
A43: 0 | B43: 0.55 | C43: 0.31 | D43: 0.4 | E43: 163 | F43: [[ 51 112] | G43: 0.53929886 | I43: 0 | J43: 0.52 | K43: 0.78 | L43: 0.62 | M43: 932 | N43: [[723 209] | O43: 0.55371219 | Q43: 0 | R43: 0.48 | S43: 0.9 | T43: 0.62 | U43: 811 | V43: [[731 80] | W43: 0.59711617
A44: 1 | B44: 0.54 | C44: 0.77 | D44: 0.64 | E44: 175 | F44: [ 41 134]] | I44: 1 | J44: 0.61 | K44: 0.33 | L44: 0.43 | M44: 1004 | N44: [671 333]] | Q44: 1 | R44: 0.81 | S44: 0.29 | T44: 0.43 | U44: 1137 | V44: [804 333]]
A45: accuracy | D45: 0.55 | E45: 338 | I45: accuracy | L45: 0.55 | M45: 1936 | Q45: accuracy | T45: 0.55 | U45: 1948
...

Sheet median (1998-2023)
A1: ITA-ROE-GradientBoostingClassifier | I1: EU-ROE-GradientBoostingClassifier | Q1: USA-ROE-GradientBoostingClassifier
B2: precision | C2: recall | D2: f1-score | E2: support | F2: confusion matrix | G2: roc-auc score | J2: precision | K2: recall | L2: f1-score | M2: support | N2: confusion matrix | O2: roc-auc score | R2: precision | S2: recall | T2: f1-score | U2: support | V2: confusion matrix | W2: roc-auc score
A3: 0 | B3: 0.66 | C3: 0.65 | D3: 0.65 | E3: 192 | F3: [[124 68] | G3: 0.60373858 | I3: 0 | J3: 0.68 | K3: 0.62 | L3: 0.65 | M3: 1075 | N3: [[669 406] | O3: 0.63172028 | Q3: 0 | R3: 0.73 | S3: 0.54 | T3: 0.62 | U3: 986 | V3: [[532 454] | W3: 0.66738602
A4: 1 | B4: 0.55 | C4: 0.56 | D4: 0.55 | E4: 146 | F4: [ 64 82]] | I4: 1 | J4: 0.58 | K4: 0.64 | L4: 0.61 | M4: 861 | N4: [309 552]] | Q4: 1 | R4: 0.63 | S4: 0.8 | T4: 0.7 | U4: 962 | V4: [197 765]]
A5: accuracy | D5: 0.61 | E5: 338 | I5: accuracy | L5: 0.63 | M5: 1936 | Q5: accuracy | T5: 0.67 | U5: 1948
A6: macro avg | B6: 0.6 | C6: 0.6 | D6: 0.6 | E6: 338 | I6: macro avg | J6: 0.63 | K6: 0.63 | L6: 0.63 | M6: 1936 | Q6: macro avg | R6: 0.68 | S6: 0.67 | T6: 0.66 | U6: 1948
A7: weighted avg | B7: 0.61 | C7: 0.61 | D7: 0.61 | E7: 338 | I7: weighted avg | J7: 0.64 | K7: 0.63 | L7: 0.63 | M7: 1936 | Q7: weighted avg | R7: 0.68 | S7: 0.67 | T7: 0.66 | U7: 1948
A9: ITA-ROE-RandomForestClassifier | I9: EU-ROE-RandomForestClassifier | Q9: USA-ROE-RandomForestClassifier
B10: precision | C10: recall | D10: f1-score | E10: support | F10: confusion matrix | G10: roc-auc score | J10: precision | K10: recall | L10: f1-score | M10: support | N10: confusion matrix | O10: roc-auc score | R10: precision | S10: recall | T10: f1-score | U10: support | V10: confusion matrix | W10: roc-auc score
A11: 0 | B11: 0.66 | C11: 0.75 | D11: 0.7 | E11: 192 | F11: [[144 48] | G11: 0.61815068 | I11: 0 | J11: 0.66 | K11: 0.67 | L11: 0.67 | M11: 1075 | N11: [[723 352] | O11: 0.62257408 | Q11: 0 | R11: 0.69 | S11: 0.56 | T11: 0.62 | U11: 986 | V11: [[549 437] | W11: 0.65157844
A12: 1 | B12: 0.6 | C12: 0.49 | D12: 0.54 | E12: 146 | F12: [ 75 71]] | I12: 1 | J12: 0.58 | K12: 0.57 | L12: 0.58 | M12: 861 | N12: [368 493]] | Q12: 1 | R12: 0.62 | S12: 0.75 | T12: 0.68 | U12: 962 | V12: [244 718]]
A13: accuracy | D13: 0.64 | E13: 338 | I13: accuracy | L13: 0.63 | M13: 1936 | Q13: accuracy | T13: 0.65 | U13: 1948
A14: macro avg | B14: 0.63 | C14: 0.62 | D14: 0.62 | E14: 338 | I14: macro avg | J14: 0.62 | K14: 0.62 | L14: 0.62 | M14: 1936 | Q14: macro avg | R14: 0.66 | S14: 0.65 | T14: 0.65 | U14: 1948
A15: weighted avg | B15: 0.63 | C15: 0.64 | D15: 0.63 | E15: 338 | I15: weighted avg | J15: 0.63 | K15: 0.63 | L15: 0.63 | M15: 1936 | Q15: weighted avg | R15: 0.66 | S15: 0.65 | T15: 0.65 | U15: 1948
A17: ITA-ROE-MPLClassifier | I17: EU-ROE-MPLClassifier | Q17: USA-ROE-MPLClassifier
B18: precision | C18: recall | D18: f1-score | E18: support | F18: confusion matrix | G18: roc-auc score | J18: precision | K18: recall | L18: f1-score | M18: support | N18: confusion matrix | O18: roc-auc score | R18: precision | S18: recall | T18: f1-score | U18: support | V18: confusion matrix | W18: roc-auc score
A19: 0 | B19: 0.7 | C19: 0.28 | D19: 0.4 | E19: 192 | F19: [[ 53 139] | G19: 0.55925371 | I19: 0 | J19: 0.58 | K19: 0.01 | L19: 0.01 | M19: 1075 | N19: [[ 7 1068] | O19: 0.50035221 | Q19: 0 | R19: 0.66 | S19: 0.38 | T19: 0.48 | U19: 986 | V19: [[378 608] | W19: 0.58825322
A20: 1 | B20: 0.47 | C20: 0.84 | D20: 0.6 | E20: 146 | F20: [ 23 123]] | I20: 1 | J20: 0.44 | K20: 0.99 | L20: 0.61 | M20: 861 | N20: [ 5 856]] | Q20: 1 | R20: 0.56 | S20: 0.79 | T20: 0.65 | U20: 962 | V20: [199 763]]
A21: accuracy | D21: 0.52 | E21: 338 | I21: accuracy | L21: 0.45 | M21: 1936 | Q21: accuracy | T21: 0.59 | U21: 1948
A22: macro avg | B22: 0.58 | C22: 0.56 | D22: 0.5 | E22: 338 | I22: macro avg | J22: 0.51 | K22: 0.5 | L22: 0.31 | M22: 1936 | Q22: macro avg | R22: 0.61 | S22: 0.59 | T22: 0.57 | U22: 1948
A23: weighted avg | B23: 0.6 | C23: 0.52 | D23: 0.49 | E23: 338 | I23: weighted avg | J23: 0.52 | K23: 0.45 | L23: 0.28 | M23: 1936 | Q23: weighted avg | R23: 0.61 | S23: 0.59 | T23: 0.57 | U23: 1948
A25: ITA-ROCE-GradientBoostingClassifier | I25: EU-ROCE-GradientBoostingClassifier | Q25: USA-ROCE-GradientBoostingClassifier
B26: precision | C26: recall | D26: f1-score | E26: support | F26: confusion matrix | G26: roc-auc score | J26: precision | K26: recall | L26: f1-score | M26: support | N26: confusion matrix | O26: roc-auc score | R26: precision | S26: recall | T26: f1-score | U26: support | V26: confusion matrix | W26: roc-auc score
A27: 0 | B27: 0.57 | C27: 0.69 | D27: 0.63 | E27: 163 | F27: [[112 51] | G27: 0.60641543 | I27: 0 | J27: 0.6 | K27: 0.67 | L27: 0.63 | M27: 932 | N27: [[620 312] | O27: 0.63042679 | Q27: 0 | R27: 0.69 | S27: 0.53 | T27: 0.6 | U27: 810 | V27: [[426 384] | W27: 0.67904381
A28: 1 | B28: 0.64 | C28: 0.53 | D28: 0.58 | E28: 175 | F28: [ 83 92]] | I28: 1 | J28: 0.66 | K28: 0.6 | L28: 0.62 | M28: 1004 | N28: [406 598]] | Q28: 1 | R28: 0.71 | S28: 0.83 | T28: 0.77 | U28: 1138 | V28: [191 947]]
A29: accuracy | D29: 0.6 | E29: 338 | I29: accuracy | L29: 0.63 | M29: 1936 | Q29: accuracy | T29: 0.7 | U29: 1948
A30: macro avg | B30: 0.61 | C30: 0.61 | D30: 0.6 | E30: 338 | I30: macro avg | J30: 0.63 | K30: 0.63 | L30: 0.63 | M30: 1936 | Q30: macro avg | R30: 0.7 | S30: 0.68 | T30: 0.68 | U30: 1948
A31: weighted avg | B31: 0.61 | C31: 0.6 | D31: 0.6 | E31: 338 | I31: weighted avg | J31: 0.63 | K31: 0.63 | L31: 0.63 | M31: 1936 | Q31: weighted avg | R31: 0.7 | S31: 0.7 | T31: 0.7 | U31: 1948
A33: ITA-ROCE-RandomForestClassifier | I33: EU-ROCE-RandomForestClassifier | Q33: USA-ROCE-RandomForestClassifier
B34: precision | C34: recall | D34: f1-score | E34: support | F34: confusion matrix | G34: roc-auc score | J34: precision | K34: recall | L34: f1-score | M34: support | N34: confusion matrix | O34: roc-auc score | R34: precision | S34: recall | T34: f1-score | U34: support | V34: confusion matrix | W34: roc-auc score
A35: 0 | B35: 0.58 | C35: 0.75 | D35: 0.66 | E35: 163 | F35: [[123 40] | G35: 0.62587204 | I35: 0 | J35: 0.59 | K35: 0.65 | L35: 0.62 | M35: 932 | N35: [[605 327] | O35: 0.61939153 | Q35: 0 | R35: 0.63 | S35: 0.55 | T35: 0.59 | U35: 810 | V35: [[443 367] | W35: 0.65878192
A36: 1 | B36: 0.69 | C36: 0.5 | D36: 0.58 | E36: 175 | F36: [ 88 87]] | I36: 1 | J36: 0.64 | K36: 0.59 | L36: 0.62 | M36: 1004 | N36: [412 592]] | Q36: 1 | R36: 0.7 | S36: 0.77 | T36: 0.74 | U36: 1138 | V36: [261 877]]
A37: accuracy | D37: 0.62 | E37: 338 | I37: accuracy | L37: 0.62 | M37: 1936 | Q37: accuracy | T37: 0.68 | U37: 1948
A38: macro avg | B38: 0.63 | C38: 0.63 | D38: 0.62 | E38: 338 | I38: macro avg | J38: 0.62 | K38: 0.62 | L38: 0.62 | M38: 1936 | Q38: macro avg | R38: 0.67 | S38: 0.66 | T38: 0.66 | U38: 1948
A39: weighted avg | B39: 0.64 | C39: 0.62 | D39: 0.62 | E39: 338 | I39: weighted avg | J39: 0.62 | K39: 0.62 | L39: 0.62 | M39: 1936 | Q39: weighted avg | R39: 0.67 | S39: 0.68 | T39: 0.67 | U39: 1948
A41: ITA-ROCE-MPLClassifier | I41: EU-ROCE-MPLClassifier | Q41: USA-ROCE-MPLClassifier
B42: precision | C42: recall | D42: f1-score | E42: support | F42: confusion matrix | G42: roc-auc score | J42: precision | K42: recall | L42: f1-score | M42: support | N42: confusion matrix | O42: roc-auc score | R42: precision | S42: recall | T42: f1-score | U42: support | V42: confusion matrix | W42: roc-auc score
A43: 0 | B43: 0.46 | C43: 0.36 | D43: 0.4 | E43: 163 | F43: [[ 58 105] | G43: 0.48077125 | I43: 0 | J43: 0.57 | K43: 0.05 | L43: 0.09 | M43: 932 | N43: [[ 46 886] | O43: 0.50774584 | Q43: 0 | R43: 0.58 | S43: 0.3 | T43: 0.39 | U43: 810 | V43: [[241 569] | W43: 0.57231552
A44: 1 | B44: 0.5 | C44: 0.61 | D44: 0.55 | E44: 175 | F44: [ 69 106]] | I44: 1 | J44: 0.52 | K44: 0.97 | L44: 0.68 | M44: 1004 | N44: [ 34 970]] | Q44: 1 | R44: 0.63 | S44: 0.85 | T44: 0.72 | U44: 1138 | V44: [174 964]]
A45: accuracy | D45: 0.49 | E45: 338 | I45: accuracy | L45: 0.52 | M45: 1936 | Q45: accuracy | T45: 0.62 | U45: 1948
...

Sheet results (1998-2023)
A1: ROC-AUC | B1: ROE | D1: ROCE | F1: Utile Netto
A2: ITA | B2: =MAX('zero (1998-2023)'!G3,'zero (1998-2023)'!G11,'zero (1998-2023)'!G19,'mean (1998-2023)'!G3,'mean (1998-2023)'!G11,'mean (1998-2023)'!G19,'median (1998-2023)'!G3,'median (1998-2023)'!G11,'median (1998-2023)'!G19) -> 0.6430508 | C2: GBC (zero) | D2: =MAX('zero (1998-2023)'!G27,'zero (1998-2023)'!G35,'zero (1998-2023)'!G43,'mean (1998-2023)'!G27,'mean (1998-2023)'!G35,'mean (1998-2023)'!G43,'median (1998-2023)'!G27,'median (1998-2023)'!G35,'median (1998-2023)'!G43) -> 0.64872918 | E2: GBC (mean) | F2: =MAX('zero (1998-2023)'!G51,'zero (1998-2023)'!G59,'zero (1998-2023)'!G67,'mean (1998-2023)'!G51,'mean (1998-2023)'!G59,'mean (1998-2023)'!G66,'median (1998-2023)'!G51,'median (1998-2023)'!G59,'median (1998-2023)'!G67) -> 0.61821209 | G2: GBC (zero)
A3: EU | B3: =MAX('zero (1998-2023)'!O3,'zero (1998-2023)'!O11,'zero (1998-2023)'!O19,'mean (1998-2023)'!O3,'mean (1998-2023)'!O11,'mean (1998-2023)'!O19,'median (1998-2023)'!O3,'median (1998-2023)'!O11,'median (1998-2023)'!O19) -> 0.63620861 | C3: RFC (zero) | D3: =MAX('zero (1998-2023)'!O27,'zero (1998-2023)'!O35,'zero (1998-2023)'!O43,'mean (1998-2023)'!O27,'mean (1998-2023)'!O35,'mean (1998-2023)'!O43,'median (1998-2023)'!O27,'median (1998-2023)'!O35,'median (1998-2023)'!O43) -> 0.63042679 | E3: GBC (median) | F3: =MAX('zero (1998-2023)'!O51,'zero (1998-2023)'!O59,'zero (1998-2023)'!O67,'mean (1998-2023)'!O51,'mean (1998-2023)'!O59,'mean (1998-2023)'!O66,'median (1998-2023)'!O51,'median (1998-2023)'!O59,'median (1998-2023)'!O67) -> 0.59217578 | G3: RFC (mean)
A4: USA | B4: =MAX('zero (1998-2023)'!W3,'zero (1998-2023)'!W11,'zero (1998-2023)'!W19,'mean (1998-2023)'!W3,'mean (1998-2023)'!W11,'mean (1998-2023)'!W19,'median (1998-2023)'!W3,'median (1998-2023)'!W11,'median (1998-2023)'!W19) -> 0.67374252 | C4: GBC (mean) | D4: =MAX('zero (1998-2023)'!W27,'zero (1998-2023)'!W35,'zero (1998-2023)'!W43,'mean (1998-2023)'!W27,'mean (1998-2023)'!W35,'mean (1998-2023)'!W43,'median (1998-2023)'!W27,'median (1998-2023)'!W35,'median (1998-2023)'!W43) -> 0.68553717 | E4: GBC (zero) | F4: =MAX('zero (1998-2023)'!W51,'zero (1998-2023)'!W59,'zero (1998-2023)'!W67,'mean (1998-2023)'!W51,'mean (1998-2023)'!W59,'mean (1998-2023)'!W66,'median (1998-2023)'!W51,'median (1998-2023)'!W59,'median (1998-2023)'!W67) -> 0.6087022 | G4: GBC (mean)
A6: ACCURACY | B6: ROE | D6: ROCE | F6: Utile Netto
A7: ITA | B7: =MAX('zero (1998-2023)'!D5,'zero (1998-2023)'!D13,'zero (1998-2023)'!D21,'mean (1998-2023)'!D5,'mean (1998-2023)'!D13,'mean (1998-2023)'!D21,'median (1998-2023)'!D5,'median (1998-2023)'!D13,'median (1998-2023)'!D21) -> 0.65 | C7: GBC (mean) RFC (zero) | D7: =MAX('zero (1998-2023)'!D29,'zero (1998-2023)'!D37,'zero (1998-2023)'!D45,'mean (1998-2023)'!D29,'mean (1998-2023)'!D37,'mean (1998-2023)'!D45,'median (1998-2023)'!D29,'median (1998-2023)'!D37,'median (1998-2023)'!D45) -> 0.64 | E7: GBC (zero, mean) | F7: =MAX('zero (1998-2023)'!D53,'zero (1998-2023)'!D61,'zero (1998-2023)'!D69,'mean (1998-2023)'!D53,'mean (1998-2023)'!D61,'mean (1998-2023)'!D69,'median (1998-2023)'!D53,'median (1998-2023)'!D61,'median (1998-2023)'!D69) -> 0.62 | G7: GBC (zero) RFC (median)
A8: EU | B8: =MAX('zero (1998-2023)'!L5,'zero (1998-2023)'!L13,'zero (1998-2023)'!L21,'mean (1998-2023)'!L5,'mean (1998-2023)'!L13,'mean (1998-2023)'!L21,'median (1998-2023)'!L5,'median (1998-2023)'!L13,'median (1998-2023)'!L21) -> 0.64 | C8: RFC (zero, mean) | D8: =MAX('zero (1998-2023)'!L29,'zero (1998-2023)'!L37,'zero (1998-2023)'!L45,'mean (1998-2023)'!L29,'mean (1998-2023)'!L37,'mean (1998-2023)'!L45,'median (1998-2023)'!L29,'median (1998-2023)'!L37,'median (1998-2023)'!L45) -> 0.63 | E8: GBC (mean, median) RFC (mean) | F8: =MAX('zero (1998-2023)'!L53,'zero (1998-2023)'!L61,'zero (1998-2023)'!L69,'mean (1998-2023)'!L53,'mean (1998-2023)'!L61,'mean (1998-2023)'!L69,'median (1998-2023)'!L53,'median (1998-2023)'!L61,'median (1998-2023)'!L69) -> 0.6 | G8: RFC (mean)
A9: USA | B9: =MAX('zero (1998-2023)'!T5,'zero (1998-2023)'!T13,'zero (1998-2023)'!T21,'mean (1998-2023)'!T5,'mean (1998-2023)'!T13,'mean (1998-2023)'!T21,'median (1998-2023)'!T5,'median (1998-2023)'!T13,'median (1998-2023)'!T21) -> 0.67 | C9: GBC (zero, mean, median) | D9: =MAX('zero (1998-2023)'!T29,'zero (1998-2023)'!T37,'zero (1998-2023)'!T45,'mean (1998-2023)'!T29,'mean (1998-2023)'!T37,'mean (1998-2023)'!T45,'median (1998-2023)'!T29,'median (1998-2023)'!T37,'median (1998-2023)'!T45) -> 0.71 | E9: GBC (zero) | F9: =MAX('zero (1998-2023)'!T53,'zero (1998-2023)'!T61,'zero (1998-2023)'!T69,'mean (1998-2023)'!T53,'mean (1998-2023)'!T61,'mean (1998-2023)'!T69,'median (1998-2023)'!T53,'median (1998-2023)'!T61,'median (1998-2023)'!T69) -> 0.63 | G9: GBC (zero, mean, median)
